2021-05-31 22:14:41,873 -  nornir.core -     INFO -        run() - Running task 'send_command' with args {'command': 'show version'} on 3 hosts
2021-05-31 22:14:42,868 - nornir.core.task -    ERROR -      start() - Host 'RT31': task 'send_command' failed with traceback:
Traceback (most recent call last):
  File "/home/pzharyuk/Documents/fastAPI-nornir/.venv/lib/python3.8/site-packages/nornir/core/task.py", line 99, in start
    r = self.task(self, **self.params)
  File "/home/pzharyuk/Documents/fastAPI-nornir/.venv/lib/python3.8/site-packages/nornir_scrapli/tasks/send_command.py", line 36, in send_command
    scrapli_conn = task.host.get_connection("scrapli", task.nornir.config)
  File "/home/pzharyuk/Documents/fastAPI-nornir/.venv/lib/python3.8/site-packages/nornir/core/inventory.py", line 494, in get_connection
    self.open_connection(
  File "/home/pzharyuk/Documents/fastAPI-nornir/.venv/lib/python3.8/site-packages/nornir/core/inventory.py", line 546, in open_connection
    conn_obj.open(
  File "/home/pzharyuk/Documents/fastAPI-nornir/.venv/lib/python3.8/site-packages/nornir_scrapli/connection.py", line 93, in open
    connection.open()
  File "/home/pzharyuk/Documents/fastAPI-nornir/.venv/lib/python3.8/site-packages/scrapli/driver/base/sync_driver.py", line 85, in open
    self.channel.channel_authenticate_ssh(
  File "/home/pzharyuk/Documents/fastAPI-nornir/.venv/lib/python3.8/site-packages/scrapli/decorators.py", line 275, in decorate
    return self._multiprocessing_timeout(
  File "/home/pzharyuk/Documents/fastAPI-nornir/.venv/lib/python3.8/site-packages/scrapli/decorators.py", line 336, in _multiprocessing_timeout
    return future.result()
  File "/usr/lib/python3.8/concurrent/futures/_base.py", line 432, in result
    return self.__get_result()
  File "/usr/lib/python3.8/concurrent/futures/_base.py", line 388, in __get_result
    raise self._exception
  File "/usr/lib/python3.8/concurrent/futures/thread.py", line 57, in run
    result = self.fn(*self.args, **self.kwargs)
  File "/home/pzharyuk/Documents/fastAPI-nornir/.venv/lib/python3.8/site-packages/scrapli/channel/sync_channel.py", line 243, in channel_authenticate_ssh
    self._ssh_message_handler(output=authenticate_buf)
  File "/home/pzharyuk/Documents/fastAPI-nornir/.venv/lib/python3.8/site-packages/scrapli/channel/base_channel.py", line 200, in _ssh_message_handler
    raise ScrapliAuthenticationFailed(msg)
scrapli.exceptions.ScrapliAuthenticationFailed: No matching key exchange found for host, their offer: diffie-hellman-group-exchange-sha1,diffie-hellman-group14-sha1

2021-05-31 22:14:42,966 - nornir.core.task -    ERROR -      start() - Host 'RTR2': task 'send_command' failed with traceback:
Traceback (most recent call last):
  File "/home/pzharyuk/Documents/fastAPI-nornir/.venv/lib/python3.8/site-packages/nornir/core/task.py", line 99, in start
    r = self.task(self, **self.params)
  File "/home/pzharyuk/Documents/fastAPI-nornir/.venv/lib/python3.8/site-packages/nornir_scrapli/tasks/send_command.py", line 36, in send_command
    scrapli_conn = task.host.get_connection("scrapli", task.nornir.config)
  File "/home/pzharyuk/Documents/fastAPI-nornir/.venv/lib/python3.8/site-packages/nornir/core/inventory.py", line 494, in get_connection
    self.open_connection(
  File "/home/pzharyuk/Documents/fastAPI-nornir/.venv/lib/python3.8/site-packages/nornir/core/inventory.py", line 546, in open_connection
    conn_obj.open(
  File "/home/pzharyuk/Documents/fastAPI-nornir/.venv/lib/python3.8/site-packages/nornir_scrapli/connection.py", line 93, in open
    connection.open()
  File "/home/pzharyuk/Documents/fastAPI-nornir/.venv/lib/python3.8/site-packages/scrapli/driver/base/sync_driver.py", line 85, in open
    self.channel.channel_authenticate_ssh(
  File "/home/pzharyuk/Documents/fastAPI-nornir/.venv/lib/python3.8/site-packages/scrapli/decorators.py", line 275, in decorate
    return self._multiprocessing_timeout(
  File "/home/pzharyuk/Documents/fastAPI-nornir/.venv/lib/python3.8/site-packages/scrapli/decorators.py", line 336, in _multiprocessing_timeout
    return future.result()
  File "/usr/lib/python3.8/concurrent/futures/_base.py", line 432, in result
    return self.__get_result()
  File "/usr/lib/python3.8/concurrent/futures/_base.py", line 388, in __get_result
    raise self._exception
  File "/usr/lib/python3.8/concurrent/futures/thread.py", line 57, in run
    result = self.fn(*self.args, **self.kwargs)
  File "/home/pzharyuk/Documents/fastAPI-nornir/.venv/lib/python3.8/site-packages/scrapli/channel/sync_channel.py", line 243, in channel_authenticate_ssh
    self._ssh_message_handler(output=authenticate_buf)
  File "/home/pzharyuk/Documents/fastAPI-nornir/.venv/lib/python3.8/site-packages/scrapli/channel/base_channel.py", line 200, in _ssh_message_handler
    raise ScrapliAuthenticationFailed(msg)
scrapli.exceptions.ScrapliAuthenticationFailed: No matching key exchange found for host, their offer: diffie-hellman-group-exchange-sha1,diffie-hellman-group14-sha1

2021-05-31 22:14:43,024 - nornir.core.task -    ERROR -      start() - Host 'RTR1': task 'send_command' failed with traceback:
Traceback (most recent call last):
  File "/home/pzharyuk/Documents/fastAPI-nornir/.venv/lib/python3.8/site-packages/nornir/core/task.py", line 99, in start
    r = self.task(self, **self.params)
  File "/home/pzharyuk/Documents/fastAPI-nornir/.venv/lib/python3.8/site-packages/nornir_scrapli/tasks/send_command.py", line 36, in send_command
    scrapli_conn = task.host.get_connection("scrapli", task.nornir.config)
  File "/home/pzharyuk/Documents/fastAPI-nornir/.venv/lib/python3.8/site-packages/nornir/core/inventory.py", line 494, in get_connection
    self.open_connection(
  File "/home/pzharyuk/Documents/fastAPI-nornir/.venv/lib/python3.8/site-packages/nornir/core/inventory.py", line 546, in open_connection
    conn_obj.open(
  File "/home/pzharyuk/Documents/fastAPI-nornir/.venv/lib/python3.8/site-packages/nornir_scrapli/connection.py", line 93, in open
    connection.open()
  File "/home/pzharyuk/Documents/fastAPI-nornir/.venv/lib/python3.8/site-packages/scrapli/driver/base/sync_driver.py", line 85, in open
    self.channel.channel_authenticate_ssh(
  File "/home/pzharyuk/Documents/fastAPI-nornir/.venv/lib/python3.8/site-packages/scrapli/decorators.py", line 275, in decorate
    return self._multiprocessing_timeout(
  File "/home/pzharyuk/Documents/fastAPI-nornir/.venv/lib/python3.8/site-packages/scrapli/decorators.py", line 336, in _multiprocessing_timeout
    return future.result()
  File "/usr/lib/python3.8/concurrent/futures/_base.py", line 432, in result
    return self.__get_result()
  File "/usr/lib/python3.8/concurrent/futures/_base.py", line 388, in __get_result
    raise self._exception
  File "/usr/lib/python3.8/concurrent/futures/thread.py", line 57, in run
    result = self.fn(*self.args, **self.kwargs)
  File "/home/pzharyuk/Documents/fastAPI-nornir/.venv/lib/python3.8/site-packages/scrapli/channel/sync_channel.py", line 243, in channel_authenticate_ssh
    self._ssh_message_handler(output=authenticate_buf)
  File "/home/pzharyuk/Documents/fastAPI-nornir/.venv/lib/python3.8/site-packages/scrapli/channel/base_channel.py", line 200, in _ssh_message_handler
    raise ScrapliAuthenticationFailed(msg)
scrapli.exceptions.ScrapliAuthenticationFailed: No matching key exchange found for host, their offer: diffie-hellman-group-exchange-sha1,diffie-hellman-group14-sha1

2021-05-31 22:15:15,680 -  nornir.core -     INFO -        run() - Running task 'send_command' with args {'command': 'show version'} on 3 hosts
2021-05-31 22:15:16,860 - nornir.core.task -    ERROR -      start() - Host 'RTR1': task 'send_command' failed with traceback:
Traceback (most recent call last):
  File "/home/pzharyuk/Documents/fastAPI-nornir/.venv/lib/python3.8/site-packages/nornir/core/task.py", line 99, in start
    r = self.task(self, **self.params)
  File "/home/pzharyuk/Documents/fastAPI-nornir/.venv/lib/python3.8/site-packages/nornir_scrapli/tasks/send_command.py", line 36, in send_command
    scrapli_conn = task.host.get_connection("scrapli", task.nornir.config)
  File "/home/pzharyuk/Documents/fastAPI-nornir/.venv/lib/python3.8/site-packages/nornir/core/inventory.py", line 494, in get_connection
    self.open_connection(
  File "/home/pzharyuk/Documents/fastAPI-nornir/.venv/lib/python3.8/site-packages/nornir/core/inventory.py", line 546, in open_connection
    conn_obj.open(
  File "/home/pzharyuk/Documents/fastAPI-nornir/.venv/lib/python3.8/site-packages/nornir_scrapli/connection.py", line 93, in open
    connection.open()
  File "/home/pzharyuk/Documents/fastAPI-nornir/.venv/lib/python3.8/site-packages/scrapli/driver/base/sync_driver.py", line 85, in open
    self.channel.channel_authenticate_ssh(
  File "/home/pzharyuk/Documents/fastAPI-nornir/.venv/lib/python3.8/site-packages/scrapli/decorators.py", line 275, in decorate
    return self._multiprocessing_timeout(
  File "/home/pzharyuk/Documents/fastAPI-nornir/.venv/lib/python3.8/site-packages/scrapli/decorators.py", line 336, in _multiprocessing_timeout
    return future.result()
  File "/usr/lib/python3.8/concurrent/futures/_base.py", line 432, in result
    return self.__get_result()
  File "/usr/lib/python3.8/concurrent/futures/_base.py", line 388, in __get_result
    raise self._exception
  File "/usr/lib/python3.8/concurrent/futures/thread.py", line 57, in run
    result = self.fn(*self.args, **self.kwargs)
  File "/home/pzharyuk/Documents/fastAPI-nornir/.venv/lib/python3.8/site-packages/scrapli/channel/sync_channel.py", line 243, in channel_authenticate_ssh
    self._ssh_message_handler(output=authenticate_buf)
  File "/home/pzharyuk/Documents/fastAPI-nornir/.venv/lib/python3.8/site-packages/scrapli/channel/base_channel.py", line 200, in _ssh_message_handler
    raise ScrapliAuthenticationFailed(msg)
scrapli.exceptions.ScrapliAuthenticationFailed: No matching key exchange found for host, their offer: diffie-hellman-group-exchange-sha1,diffie-hellman-group14-sha1

2021-05-31 22:15:16,892 - nornir.core.task -    ERROR -      start() - Host 'RTR2': task 'send_command' failed with traceback:
Traceback (most recent call last):
  File "/home/pzharyuk/Documents/fastAPI-nornir/.venv/lib/python3.8/site-packages/nornir/core/task.py", line 99, in start
    r = self.task(self, **self.params)
  File "/home/pzharyuk/Documents/fastAPI-nornir/.venv/lib/python3.8/site-packages/nornir_scrapli/tasks/send_command.py", line 36, in send_command
    scrapli_conn = task.host.get_connection("scrapli", task.nornir.config)
  File "/home/pzharyuk/Documents/fastAPI-nornir/.venv/lib/python3.8/site-packages/nornir/core/inventory.py", line 494, in get_connection
    self.open_connection(
  File "/home/pzharyuk/Documents/fastAPI-nornir/.venv/lib/python3.8/site-packages/nornir/core/inventory.py", line 546, in open_connection
    conn_obj.open(
  File "/home/pzharyuk/Documents/fastAPI-nornir/.venv/lib/python3.8/site-packages/nornir_scrapli/connection.py", line 93, in open
    connection.open()
  File "/home/pzharyuk/Documents/fastAPI-nornir/.venv/lib/python3.8/site-packages/scrapli/driver/base/sync_driver.py", line 85, in open
    self.channel.channel_authenticate_ssh(
  File "/home/pzharyuk/Documents/fastAPI-nornir/.venv/lib/python3.8/site-packages/scrapli/decorators.py", line 275, in decorate
    return self._multiprocessing_timeout(
  File "/home/pzharyuk/Documents/fastAPI-nornir/.venv/lib/python3.8/site-packages/scrapli/decorators.py", line 336, in _multiprocessing_timeout
    return future.result()
  File "/usr/lib/python3.8/concurrent/futures/_base.py", line 432, in result
    return self.__get_result()
  File "/usr/lib/python3.8/concurrent/futures/_base.py", line 388, in __get_result
    raise self._exception
  File "/usr/lib/python3.8/concurrent/futures/thread.py", line 57, in run
    result = self.fn(*self.args, **self.kwargs)
  File "/home/pzharyuk/Documents/fastAPI-nornir/.venv/lib/python3.8/site-packages/scrapli/channel/sync_channel.py", line 243, in channel_authenticate_ssh
    self._ssh_message_handler(output=authenticate_buf)
  File "/home/pzharyuk/Documents/fastAPI-nornir/.venv/lib/python3.8/site-packages/scrapli/channel/base_channel.py", line 200, in _ssh_message_handler
    raise ScrapliAuthenticationFailed(msg)
scrapli.exceptions.ScrapliAuthenticationFailed: No matching key exchange found for host, their offer: diffie-hellman-group-exchange-sha1,diffie-hellman-group14-sha1

2021-05-31 22:15:16,933 - nornir.core.task -    ERROR -      start() - Host 'RT31': task 'send_command' failed with traceback:
Traceback (most recent call last):
  File "/home/pzharyuk/Documents/fastAPI-nornir/.venv/lib/python3.8/site-packages/nornir/core/task.py", line 99, in start
    r = self.task(self, **self.params)
  File "/home/pzharyuk/Documents/fastAPI-nornir/.venv/lib/python3.8/site-packages/nornir_scrapli/tasks/send_command.py", line 36, in send_command
    scrapli_conn = task.host.get_connection("scrapli", task.nornir.config)
  File "/home/pzharyuk/Documents/fastAPI-nornir/.venv/lib/python3.8/site-packages/nornir/core/inventory.py", line 494, in get_connection
    self.open_connection(
  File "/home/pzharyuk/Documents/fastAPI-nornir/.venv/lib/python3.8/site-packages/nornir/core/inventory.py", line 546, in open_connection
    conn_obj.open(
  File "/home/pzharyuk/Documents/fastAPI-nornir/.venv/lib/python3.8/site-packages/nornir_scrapli/connection.py", line 93, in open
    connection.open()
  File "/home/pzharyuk/Documents/fastAPI-nornir/.venv/lib/python3.8/site-packages/scrapli/driver/base/sync_driver.py", line 85, in open
    self.channel.channel_authenticate_ssh(
  File "/home/pzharyuk/Documents/fastAPI-nornir/.venv/lib/python3.8/site-packages/scrapli/decorators.py", line 275, in decorate
    return self._multiprocessing_timeout(
  File "/home/pzharyuk/Documents/fastAPI-nornir/.venv/lib/python3.8/site-packages/scrapli/decorators.py", line 336, in _multiprocessing_timeout
    return future.result()
  File "/usr/lib/python3.8/concurrent/futures/_base.py", line 432, in result
    return self.__get_result()
  File "/usr/lib/python3.8/concurrent/futures/_base.py", line 388, in __get_result
    raise self._exception
  File "/usr/lib/python3.8/concurrent/futures/thread.py", line 57, in run
    result = self.fn(*self.args, **self.kwargs)
  File "/home/pzharyuk/Documents/fastAPI-nornir/.venv/lib/python3.8/site-packages/scrapli/channel/sync_channel.py", line 243, in channel_authenticate_ssh
    self._ssh_message_handler(output=authenticate_buf)
  File "/home/pzharyuk/Documents/fastAPI-nornir/.venv/lib/python3.8/site-packages/scrapli/channel/base_channel.py", line 200, in _ssh_message_handler
    raise ScrapliAuthenticationFailed(msg)
scrapli.exceptions.ScrapliAuthenticationFailed: No matching key exchange found for host, their offer: diffie-hellman-group-exchange-sha1,diffie-hellman-group14-sha1

2021-05-31 22:15:45,868 -  nornir.core -     INFO -        run() - Running task 'send_command' with args {'command': 'show version'} on 3 hosts
2021-05-31 22:15:46,994 - nornir.core.task -    ERROR -      start() - Host 'RT31': task 'send_command' failed with traceback:
Traceback (most recent call last):
  File "/home/pzharyuk/Documents/fastAPI-nornir/.venv/lib/python3.8/site-packages/nornir/core/task.py", line 99, in start
    r = self.task(self, **self.params)
  File "/home/pzharyuk/Documents/fastAPI-nornir/.venv/lib/python3.8/site-packages/nornir_scrapli/tasks/send_command.py", line 36, in send_command
    scrapli_conn = task.host.get_connection("scrapli", task.nornir.config)
  File "/home/pzharyuk/Documents/fastAPI-nornir/.venv/lib/python3.8/site-packages/nornir/core/inventory.py", line 494, in get_connection
    self.open_connection(
  File "/home/pzharyuk/Documents/fastAPI-nornir/.venv/lib/python3.8/site-packages/nornir/core/inventory.py", line 546, in open_connection
    conn_obj.open(
  File "/home/pzharyuk/Documents/fastAPI-nornir/.venv/lib/python3.8/site-packages/nornir_scrapli/connection.py", line 93, in open
    connection.open()
  File "/home/pzharyuk/Documents/fastAPI-nornir/.venv/lib/python3.8/site-packages/scrapli/driver/base/sync_driver.py", line 85, in open
    self.channel.channel_authenticate_ssh(
  File "/home/pzharyuk/Documents/fastAPI-nornir/.venv/lib/python3.8/site-packages/scrapli/decorators.py", line 275, in decorate
    return self._multiprocessing_timeout(
  File "/home/pzharyuk/Documents/fastAPI-nornir/.venv/lib/python3.8/site-packages/scrapli/decorators.py", line 336, in _multiprocessing_timeout
    return future.result()
  File "/usr/lib/python3.8/concurrent/futures/_base.py", line 432, in result
    return self.__get_result()
  File "/usr/lib/python3.8/concurrent/futures/_base.py", line 388, in __get_result
    raise self._exception
  File "/usr/lib/python3.8/concurrent/futures/thread.py", line 57, in run
    result = self.fn(*self.args, **self.kwargs)
  File "/home/pzharyuk/Documents/fastAPI-nornir/.venv/lib/python3.8/site-packages/scrapli/channel/sync_channel.py", line 243, in channel_authenticate_ssh
    self._ssh_message_handler(output=authenticate_buf)
  File "/home/pzharyuk/Documents/fastAPI-nornir/.venv/lib/python3.8/site-packages/scrapli/channel/base_channel.py", line 200, in _ssh_message_handler
    raise ScrapliAuthenticationFailed(msg)
scrapli.exceptions.ScrapliAuthenticationFailed: No matching key exchange found for host, their offer: diffie-hellman-group-exchange-sha1,diffie-hellman-group14-sha1

2021-05-31 22:15:47,029 - nornir.core.task -    ERROR -      start() - Host 'RTR1': task 'send_command' failed with traceback:
Traceback (most recent call last):
  File "/home/pzharyuk/Documents/fastAPI-nornir/.venv/lib/python3.8/site-packages/nornir/core/task.py", line 99, in start
    r = self.task(self, **self.params)
  File "/home/pzharyuk/Documents/fastAPI-nornir/.venv/lib/python3.8/site-packages/nornir_scrapli/tasks/send_command.py", line 36, in send_command
    scrapli_conn = task.host.get_connection("scrapli", task.nornir.config)
  File "/home/pzharyuk/Documents/fastAPI-nornir/.venv/lib/python3.8/site-packages/nornir/core/inventory.py", line 494, in get_connection
    self.open_connection(
  File "/home/pzharyuk/Documents/fastAPI-nornir/.venv/lib/python3.8/site-packages/nornir/core/inventory.py", line 546, in open_connection
    conn_obj.open(
  File "/home/pzharyuk/Documents/fastAPI-nornir/.venv/lib/python3.8/site-packages/nornir_scrapli/connection.py", line 93, in open
    connection.open()
  File "/home/pzharyuk/Documents/fastAPI-nornir/.venv/lib/python3.8/site-packages/scrapli/driver/base/sync_driver.py", line 85, in open
    self.channel.channel_authenticate_ssh(
  File "/home/pzharyuk/Documents/fastAPI-nornir/.venv/lib/python3.8/site-packages/scrapli/decorators.py", line 275, in decorate
    return self._multiprocessing_timeout(
  File "/home/pzharyuk/Documents/fastAPI-nornir/.venv/lib/python3.8/site-packages/scrapli/decorators.py", line 336, in _multiprocessing_timeout
    return future.result()
  File "/usr/lib/python3.8/concurrent/futures/_base.py", line 432, in result
    return self.__get_result()
  File "/usr/lib/python3.8/concurrent/futures/_base.py", line 388, in __get_result
    raise self._exception
  File "/usr/lib/python3.8/concurrent/futures/thread.py", line 57, in run
    result = self.fn(*self.args, **self.kwargs)
  File "/home/pzharyuk/Documents/fastAPI-nornir/.venv/lib/python3.8/site-packages/scrapli/channel/sync_channel.py", line 243, in channel_authenticate_ssh
    self._ssh_message_handler(output=authenticate_buf)
  File "/home/pzharyuk/Documents/fastAPI-nornir/.venv/lib/python3.8/site-packages/scrapli/channel/base_channel.py", line 200, in _ssh_message_handler
    raise ScrapliAuthenticationFailed(msg)
scrapli.exceptions.ScrapliAuthenticationFailed: No matching key exchange found for host, their offer: diffie-hellman-group-exchange-sha1,diffie-hellman-group14-sha1

2021-05-31 22:15:47,040 - nornir.core.task -    ERROR -      start() - Host 'RTR2': task 'send_command' failed with traceback:
Traceback (most recent call last):
  File "/home/pzharyuk/Documents/fastAPI-nornir/.venv/lib/python3.8/site-packages/nornir/core/task.py", line 99, in start
    r = self.task(self, **self.params)
  File "/home/pzharyuk/Documents/fastAPI-nornir/.venv/lib/python3.8/site-packages/nornir_scrapli/tasks/send_command.py", line 36, in send_command
    scrapli_conn = task.host.get_connection("scrapli", task.nornir.config)
  File "/home/pzharyuk/Documents/fastAPI-nornir/.venv/lib/python3.8/site-packages/nornir/core/inventory.py", line 494, in get_connection
    self.open_connection(
  File "/home/pzharyuk/Documents/fastAPI-nornir/.venv/lib/python3.8/site-packages/nornir/core/inventory.py", line 546, in open_connection
    conn_obj.open(
  File "/home/pzharyuk/Documents/fastAPI-nornir/.venv/lib/python3.8/site-packages/nornir_scrapli/connection.py", line 93, in open
    connection.open()
  File "/home/pzharyuk/Documents/fastAPI-nornir/.venv/lib/python3.8/site-packages/scrapli/driver/base/sync_driver.py", line 85, in open
    self.channel.channel_authenticate_ssh(
  File "/home/pzharyuk/Documents/fastAPI-nornir/.venv/lib/python3.8/site-packages/scrapli/decorators.py", line 275, in decorate
    return self._multiprocessing_timeout(
  File "/home/pzharyuk/Documents/fastAPI-nornir/.venv/lib/python3.8/site-packages/scrapli/decorators.py", line 336, in _multiprocessing_timeout
    return future.result()
  File "/usr/lib/python3.8/concurrent/futures/_base.py", line 432, in result
    return self.__get_result()
  File "/usr/lib/python3.8/concurrent/futures/_base.py", line 388, in __get_result
    raise self._exception
  File "/usr/lib/python3.8/concurrent/futures/thread.py", line 57, in run
    result = self.fn(*self.args, **self.kwargs)
  File "/home/pzharyuk/Documents/fastAPI-nornir/.venv/lib/python3.8/site-packages/scrapli/channel/sync_channel.py", line 243, in channel_authenticate_ssh
    self._ssh_message_handler(output=authenticate_buf)
  File "/home/pzharyuk/Documents/fastAPI-nornir/.venv/lib/python3.8/site-packages/scrapli/channel/base_channel.py", line 200, in _ssh_message_handler
    raise ScrapliAuthenticationFailed(msg)
scrapli.exceptions.ScrapliAuthenticationFailed: No matching key exchange found for host, their offer: diffie-hellman-group-exchange-sha1,diffie-hellman-group14-sha1

2021-05-31 22:28:43,932 -  nornir.core -     INFO -        run() - Running task 'send_command' with args {'command': 'show version'} on 3 hosts
2021-05-31 22:28:45,075 - nornir.core.task -    ERROR -      start() - Host 'RTR2': task 'send_command' failed with traceback:
Traceback (most recent call last):
  File "/home/pzharyuk/Documents/fastAPI-nornir/.venv/lib/python3.8/site-packages/nornir/core/task.py", line 99, in start
    r = self.task(self, **self.params)
  File "/home/pzharyuk/Documents/fastAPI-nornir/.venv/lib/python3.8/site-packages/nornir_scrapli/tasks/send_command.py", line 36, in send_command
    scrapli_conn = task.host.get_connection("scrapli", task.nornir.config)
  File "/home/pzharyuk/Documents/fastAPI-nornir/.venv/lib/python3.8/site-packages/nornir/core/inventory.py", line 494, in get_connection
    self.open_connection(
  File "/home/pzharyuk/Documents/fastAPI-nornir/.venv/lib/python3.8/site-packages/nornir/core/inventory.py", line 546, in open_connection
    conn_obj.open(
  File "/home/pzharyuk/Documents/fastAPI-nornir/.venv/lib/python3.8/site-packages/nornir_scrapli/connection.py", line 93, in open
    connection.open()
  File "/home/pzharyuk/Documents/fastAPI-nornir/.venv/lib/python3.8/site-packages/scrapli/driver/base/sync_driver.py", line 85, in open
    self.channel.channel_authenticate_ssh(
  File "/home/pzharyuk/Documents/fastAPI-nornir/.venv/lib/python3.8/site-packages/scrapli/decorators.py", line 275, in decorate
    return self._multiprocessing_timeout(
  File "/home/pzharyuk/Documents/fastAPI-nornir/.venv/lib/python3.8/site-packages/scrapli/decorators.py", line 336, in _multiprocessing_timeout
    return future.result()
  File "/usr/lib/python3.8/concurrent/futures/_base.py", line 432, in result
    return self.__get_result()
  File "/usr/lib/python3.8/concurrent/futures/_base.py", line 388, in __get_result
    raise self._exception
  File "/usr/lib/python3.8/concurrent/futures/thread.py", line 57, in run
    result = self.fn(*self.args, **self.kwargs)
  File "/home/pzharyuk/Documents/fastAPI-nornir/.venv/lib/python3.8/site-packages/scrapli/channel/sync_channel.py", line 243, in channel_authenticate_ssh
    self._ssh_message_handler(output=authenticate_buf)
  File "/home/pzharyuk/Documents/fastAPI-nornir/.venv/lib/python3.8/site-packages/scrapli/channel/base_channel.py", line 200, in _ssh_message_handler
    raise ScrapliAuthenticationFailed(msg)
scrapli.exceptions.ScrapliAuthenticationFailed: No matching key exchange found for host, their offer: diffie-hellman-group-exchange-sha1,diffie-hellman-group14-sha1

2021-05-31 22:28:45,082 - nornir.core.task -    ERROR -      start() - Host 'RT31': task 'send_command' failed with traceback:
Traceback (most recent call last):
  File "/home/pzharyuk/Documents/fastAPI-nornir/.venv/lib/python3.8/site-packages/nornir/core/task.py", line 99, in start
    r = self.task(self, **self.params)
  File "/home/pzharyuk/Documents/fastAPI-nornir/.venv/lib/python3.8/site-packages/nornir_scrapli/tasks/send_command.py", line 36, in send_command
    scrapli_conn = task.host.get_connection("scrapli", task.nornir.config)
  File "/home/pzharyuk/Documents/fastAPI-nornir/.venv/lib/python3.8/site-packages/nornir/core/inventory.py", line 494, in get_connection
    self.open_connection(
  File "/home/pzharyuk/Documents/fastAPI-nornir/.venv/lib/python3.8/site-packages/nornir/core/inventory.py", line 546, in open_connection
    conn_obj.open(
  File "/home/pzharyuk/Documents/fastAPI-nornir/.venv/lib/python3.8/site-packages/nornir_scrapli/connection.py", line 93, in open
    connection.open()
  File "/home/pzharyuk/Documents/fastAPI-nornir/.venv/lib/python3.8/site-packages/scrapli/driver/base/sync_driver.py", line 85, in open
    self.channel.channel_authenticate_ssh(
  File "/home/pzharyuk/Documents/fastAPI-nornir/.venv/lib/python3.8/site-packages/scrapli/decorators.py", line 275, in decorate
    return self._multiprocessing_timeout(
  File "/home/pzharyuk/Documents/fastAPI-nornir/.venv/lib/python3.8/site-packages/scrapli/decorators.py", line 336, in _multiprocessing_timeout
    return future.result()
  File "/usr/lib/python3.8/concurrent/futures/_base.py", line 432, in result
    return self.__get_result()
  File "/usr/lib/python3.8/concurrent/futures/_base.py", line 388, in __get_result
    raise self._exception
  File "/usr/lib/python3.8/concurrent/futures/thread.py", line 57, in run
    result = self.fn(*self.args, **self.kwargs)
  File "/home/pzharyuk/Documents/fastAPI-nornir/.venv/lib/python3.8/site-packages/scrapli/channel/sync_channel.py", line 243, in channel_authenticate_ssh
    self._ssh_message_handler(output=authenticate_buf)
  File "/home/pzharyuk/Documents/fastAPI-nornir/.venv/lib/python3.8/site-packages/scrapli/channel/base_channel.py", line 200, in _ssh_message_handler
    raise ScrapliAuthenticationFailed(msg)
scrapli.exceptions.ScrapliAuthenticationFailed: No matching key exchange found for host, their offer: diffie-hellman-group-exchange-sha1,diffie-hellman-group14-sha1

2021-05-31 22:28:45,132 - nornir.core.task -    ERROR -      start() - Host 'RTR1': task 'send_command' failed with traceback:
Traceback (most recent call last):
  File "/home/pzharyuk/Documents/fastAPI-nornir/.venv/lib/python3.8/site-packages/nornir/core/task.py", line 99, in start
    r = self.task(self, **self.params)
  File "/home/pzharyuk/Documents/fastAPI-nornir/.venv/lib/python3.8/site-packages/nornir_scrapli/tasks/send_command.py", line 36, in send_command
    scrapli_conn = task.host.get_connection("scrapli", task.nornir.config)
  File "/home/pzharyuk/Documents/fastAPI-nornir/.venv/lib/python3.8/site-packages/nornir/core/inventory.py", line 494, in get_connection
    self.open_connection(
  File "/home/pzharyuk/Documents/fastAPI-nornir/.venv/lib/python3.8/site-packages/nornir/core/inventory.py", line 546, in open_connection
    conn_obj.open(
  File "/home/pzharyuk/Documents/fastAPI-nornir/.venv/lib/python3.8/site-packages/nornir_scrapli/connection.py", line 93, in open
    connection.open()
  File "/home/pzharyuk/Documents/fastAPI-nornir/.venv/lib/python3.8/site-packages/scrapli/driver/base/sync_driver.py", line 85, in open
    self.channel.channel_authenticate_ssh(
  File "/home/pzharyuk/Documents/fastAPI-nornir/.venv/lib/python3.8/site-packages/scrapli/decorators.py", line 275, in decorate
    return self._multiprocessing_timeout(
  File "/home/pzharyuk/Documents/fastAPI-nornir/.venv/lib/python3.8/site-packages/scrapli/decorators.py", line 336, in _multiprocessing_timeout
    return future.result()
  File "/usr/lib/python3.8/concurrent/futures/_base.py", line 432, in result
    return self.__get_result()
  File "/usr/lib/python3.8/concurrent/futures/_base.py", line 388, in __get_result
    raise self._exception
  File "/usr/lib/python3.8/concurrent/futures/thread.py", line 57, in run
    result = self.fn(*self.args, **self.kwargs)
  File "/home/pzharyuk/Documents/fastAPI-nornir/.venv/lib/python3.8/site-packages/scrapli/channel/sync_channel.py", line 243, in channel_authenticate_ssh
    self._ssh_message_handler(output=authenticate_buf)
  File "/home/pzharyuk/Documents/fastAPI-nornir/.venv/lib/python3.8/site-packages/scrapli/channel/base_channel.py", line 200, in _ssh_message_handler
    raise ScrapliAuthenticationFailed(msg)
scrapli.exceptions.ScrapliAuthenticationFailed: No matching key exchange found for host, their offer: diffie-hellman-group-exchange-sha1,diffie-hellman-group14-sha1

2021-05-31 23:06:27,824 -  nornir.core -     INFO -        run() - Running task 'send_command' with args {'command': 'show version'} on 3 hosts
2021-05-31 23:06:28,968 - nornir.core.task -    ERROR -      start() - Host 'RTR1': task 'send_command' failed with traceback:
Traceback (most recent call last):
  File "/home/pzharyuk/Documents/fastAPI-nornir/.venv/lib/python3.8/site-packages/nornir/core/task.py", line 99, in start
    r = self.task(self, **self.params)
  File "/home/pzharyuk/Documents/fastAPI-nornir/.venv/lib/python3.8/site-packages/nornir_scrapli/tasks/send_command.py", line 36, in send_command
    scrapli_conn = task.host.get_connection("scrapli", task.nornir.config)
  File "/home/pzharyuk/Documents/fastAPI-nornir/.venv/lib/python3.8/site-packages/nornir/core/inventory.py", line 494, in get_connection
    self.open_connection(
  File "/home/pzharyuk/Documents/fastAPI-nornir/.venv/lib/python3.8/site-packages/nornir/core/inventory.py", line 546, in open_connection
    conn_obj.open(
  File "/home/pzharyuk/Documents/fastAPI-nornir/.venv/lib/python3.8/site-packages/nornir_scrapli/connection.py", line 93, in open
    connection.open()
  File "/home/pzharyuk/Documents/fastAPI-nornir/.venv/lib/python3.8/site-packages/scrapli/driver/base/sync_driver.py", line 85, in open
    self.channel.channel_authenticate_ssh(
  File "/home/pzharyuk/Documents/fastAPI-nornir/.venv/lib/python3.8/site-packages/scrapli/decorators.py", line 275, in decorate
    return self._multiprocessing_timeout(
  File "/home/pzharyuk/Documents/fastAPI-nornir/.venv/lib/python3.8/site-packages/scrapli/decorators.py", line 336, in _multiprocessing_timeout
    return future.result()
  File "/usr/lib/python3.8/concurrent/futures/_base.py", line 432, in result
    return self.__get_result()
  File "/usr/lib/python3.8/concurrent/futures/_base.py", line 388, in __get_result
    raise self._exception
  File "/usr/lib/python3.8/concurrent/futures/thread.py", line 57, in run
    result = self.fn(*self.args, **self.kwargs)
  File "/home/pzharyuk/Documents/fastAPI-nornir/.venv/lib/python3.8/site-packages/scrapli/channel/sync_channel.py", line 243, in channel_authenticate_ssh
    self._ssh_message_handler(output=authenticate_buf)
  File "/home/pzharyuk/Documents/fastAPI-nornir/.venv/lib/python3.8/site-packages/scrapli/channel/base_channel.py", line 200, in _ssh_message_handler
    raise ScrapliAuthenticationFailed(msg)
scrapli.exceptions.ScrapliAuthenticationFailed: No matching key exchange found for host, their offer: diffie-hellman-group-exchange-sha1,diffie-hellman-group14-sha1

2021-05-31 23:06:28,981 - nornir.core.task -    ERROR -      start() - Host 'RTR2': task 'send_command' failed with traceback:
Traceback (most recent call last):
  File "/home/pzharyuk/Documents/fastAPI-nornir/.venv/lib/python3.8/site-packages/nornir/core/task.py", line 99, in start
    r = self.task(self, **self.params)
  File "/home/pzharyuk/Documents/fastAPI-nornir/.venv/lib/python3.8/site-packages/nornir_scrapli/tasks/send_command.py", line 36, in send_command
    scrapli_conn = task.host.get_connection("scrapli", task.nornir.config)
  File "/home/pzharyuk/Documents/fastAPI-nornir/.venv/lib/python3.8/site-packages/nornir/core/inventory.py", line 494, in get_connection
    self.open_connection(
  File "/home/pzharyuk/Documents/fastAPI-nornir/.venv/lib/python3.8/site-packages/nornir/core/inventory.py", line 546, in open_connection
    conn_obj.open(
  File "/home/pzharyuk/Documents/fastAPI-nornir/.venv/lib/python3.8/site-packages/nornir_scrapli/connection.py", line 93, in open
    connection.open()
  File "/home/pzharyuk/Documents/fastAPI-nornir/.venv/lib/python3.8/site-packages/scrapli/driver/base/sync_driver.py", line 85, in open
    self.channel.channel_authenticate_ssh(
  File "/home/pzharyuk/Documents/fastAPI-nornir/.venv/lib/python3.8/site-packages/scrapli/decorators.py", line 275, in decorate
    return self._multiprocessing_timeout(
  File "/home/pzharyuk/Documents/fastAPI-nornir/.venv/lib/python3.8/site-packages/scrapli/decorators.py", line 336, in _multiprocessing_timeout
    return future.result()
  File "/usr/lib/python3.8/concurrent/futures/_base.py", line 432, in result
    return self.__get_result()
  File "/usr/lib/python3.8/concurrent/futures/_base.py", line 388, in __get_result
    raise self._exception
  File "/usr/lib/python3.8/concurrent/futures/thread.py", line 57, in run
    result = self.fn(*self.args, **self.kwargs)
  File "/home/pzharyuk/Documents/fastAPI-nornir/.venv/lib/python3.8/site-packages/scrapli/channel/sync_channel.py", line 243, in channel_authenticate_ssh
    self._ssh_message_handler(output=authenticate_buf)
  File "/home/pzharyuk/Documents/fastAPI-nornir/.venv/lib/python3.8/site-packages/scrapli/channel/base_channel.py", line 200, in _ssh_message_handler
    raise ScrapliAuthenticationFailed(msg)
scrapli.exceptions.ScrapliAuthenticationFailed: No matching key exchange found for host, their offer: diffie-hellman-group-exchange-sha1,diffie-hellman-group14-sha1

2021-05-31 23:06:28,993 - nornir.core.task -    ERROR -      start() - Host 'RT31': task 'send_command' failed with traceback:
Traceback (most recent call last):
  File "/home/pzharyuk/Documents/fastAPI-nornir/.venv/lib/python3.8/site-packages/nornir/core/task.py", line 99, in start
    r = self.task(self, **self.params)
  File "/home/pzharyuk/Documents/fastAPI-nornir/.venv/lib/python3.8/site-packages/nornir_scrapli/tasks/send_command.py", line 36, in send_command
    scrapli_conn = task.host.get_connection("scrapli", task.nornir.config)
  File "/home/pzharyuk/Documents/fastAPI-nornir/.venv/lib/python3.8/site-packages/nornir/core/inventory.py", line 494, in get_connection
    self.open_connection(
  File "/home/pzharyuk/Documents/fastAPI-nornir/.venv/lib/python3.8/site-packages/nornir/core/inventory.py", line 546, in open_connection
    conn_obj.open(
  File "/home/pzharyuk/Documents/fastAPI-nornir/.venv/lib/python3.8/site-packages/nornir_scrapli/connection.py", line 93, in open
    connection.open()
  File "/home/pzharyuk/Documents/fastAPI-nornir/.venv/lib/python3.8/site-packages/scrapli/driver/base/sync_driver.py", line 85, in open
    self.channel.channel_authenticate_ssh(
  File "/home/pzharyuk/Documents/fastAPI-nornir/.venv/lib/python3.8/site-packages/scrapli/decorators.py", line 275, in decorate
    return self._multiprocessing_timeout(
  File "/home/pzharyuk/Documents/fastAPI-nornir/.venv/lib/python3.8/site-packages/scrapli/decorators.py", line 336, in _multiprocessing_timeout
    return future.result()
  File "/usr/lib/python3.8/concurrent/futures/_base.py", line 432, in result
    return self.__get_result()
  File "/usr/lib/python3.8/concurrent/futures/_base.py", line 388, in __get_result
    raise self._exception
  File "/usr/lib/python3.8/concurrent/futures/thread.py", line 57, in run
    result = self.fn(*self.args, **self.kwargs)
  File "/home/pzharyuk/Documents/fastAPI-nornir/.venv/lib/python3.8/site-packages/scrapli/channel/sync_channel.py", line 243, in channel_authenticate_ssh
    self._ssh_message_handler(output=authenticate_buf)
  File "/home/pzharyuk/Documents/fastAPI-nornir/.venv/lib/python3.8/site-packages/scrapli/channel/base_channel.py", line 200, in _ssh_message_handler
    raise ScrapliAuthenticationFailed(msg)
scrapli.exceptions.ScrapliAuthenticationFailed: No matching key exchange found for host, their offer: diffie-hellman-group-exchange-sha1,diffie-hellman-group14-sha1

2021-05-31 23:12:06,887 -  nornir.core -     INFO -        run() - Running task 'send_command' with args {'command': 'show run'} on 3 hosts
2021-05-31 23:12:07,910 - nornir.core.task -    ERROR -      start() - Host 'RT31': task 'send_command' failed with traceback:
Traceback (most recent call last):
  File "/home/pzharyuk/Documents/fastAPI-nornir/.venv/lib/python3.8/site-packages/nornir/core/task.py", line 99, in start
    r = self.task(self, **self.params)
  File "/home/pzharyuk/Documents/fastAPI-nornir/.venv/lib/python3.8/site-packages/nornir_scrapli/tasks/send_command.py", line 36, in send_command
    scrapli_conn = task.host.get_connection("scrapli", task.nornir.config)
  File "/home/pzharyuk/Documents/fastAPI-nornir/.venv/lib/python3.8/site-packages/nornir/core/inventory.py", line 494, in get_connection
    self.open_connection(
  File "/home/pzharyuk/Documents/fastAPI-nornir/.venv/lib/python3.8/site-packages/nornir/core/inventory.py", line 546, in open_connection
    conn_obj.open(
  File "/home/pzharyuk/Documents/fastAPI-nornir/.venv/lib/python3.8/site-packages/nornir_scrapli/connection.py", line 93, in open
    connection.open()
  File "/home/pzharyuk/Documents/fastAPI-nornir/.venv/lib/python3.8/site-packages/scrapli/driver/base/sync_driver.py", line 85, in open
    self.channel.channel_authenticate_ssh(
  File "/home/pzharyuk/Documents/fastAPI-nornir/.venv/lib/python3.8/site-packages/scrapli/decorators.py", line 275, in decorate
    return self._multiprocessing_timeout(
  File "/home/pzharyuk/Documents/fastAPI-nornir/.venv/lib/python3.8/site-packages/scrapli/decorators.py", line 336, in _multiprocessing_timeout
    return future.result()
  File "/usr/lib/python3.8/concurrent/futures/_base.py", line 432, in result
    return self.__get_result()
  File "/usr/lib/python3.8/concurrent/futures/_base.py", line 388, in __get_result
    raise self._exception
  File "/usr/lib/python3.8/concurrent/futures/thread.py", line 57, in run
    result = self.fn(*self.args, **self.kwargs)
  File "/home/pzharyuk/Documents/fastAPI-nornir/.venv/lib/python3.8/site-packages/scrapli/channel/sync_channel.py", line 243, in channel_authenticate_ssh
    self._ssh_message_handler(output=authenticate_buf)
  File "/home/pzharyuk/Documents/fastAPI-nornir/.venv/lib/python3.8/site-packages/scrapli/channel/base_channel.py", line 200, in _ssh_message_handler
    raise ScrapliAuthenticationFailed(msg)
scrapli.exceptions.ScrapliAuthenticationFailed: No matching key exchange found for host, their offer: diffie-hellman-group-exchange-sha1,diffie-hellman-group14-sha1

2021-05-31 23:12:07,946 - nornir.core.task -    ERROR -      start() - Host 'RTR1': task 'send_command' failed with traceback:
Traceback (most recent call last):
  File "/home/pzharyuk/Documents/fastAPI-nornir/.venv/lib/python3.8/site-packages/nornir/core/task.py", line 99, in start
    r = self.task(self, **self.params)
  File "/home/pzharyuk/Documents/fastAPI-nornir/.venv/lib/python3.8/site-packages/nornir_scrapli/tasks/send_command.py", line 36, in send_command
    scrapli_conn = task.host.get_connection("scrapli", task.nornir.config)
  File "/home/pzharyuk/Documents/fastAPI-nornir/.venv/lib/python3.8/site-packages/nornir/core/inventory.py", line 494, in get_connection
    self.open_connection(
  File "/home/pzharyuk/Documents/fastAPI-nornir/.venv/lib/python3.8/site-packages/nornir/core/inventory.py", line 546, in open_connection
    conn_obj.open(
  File "/home/pzharyuk/Documents/fastAPI-nornir/.venv/lib/python3.8/site-packages/nornir_scrapli/connection.py", line 93, in open
    connection.open()
  File "/home/pzharyuk/Documents/fastAPI-nornir/.venv/lib/python3.8/site-packages/scrapli/driver/base/sync_driver.py", line 85, in open
    self.channel.channel_authenticate_ssh(
  File "/home/pzharyuk/Documents/fastAPI-nornir/.venv/lib/python3.8/site-packages/scrapli/decorators.py", line 275, in decorate
    return self._multiprocessing_timeout(
  File "/home/pzharyuk/Documents/fastAPI-nornir/.venv/lib/python3.8/site-packages/scrapli/decorators.py", line 336, in _multiprocessing_timeout
    return future.result()
  File "/usr/lib/python3.8/concurrent/futures/_base.py", line 432, in result
    return self.__get_result()
  File "/usr/lib/python3.8/concurrent/futures/_base.py", line 388, in __get_result
    raise self._exception
  File "/usr/lib/python3.8/concurrent/futures/thread.py", line 57, in run
    result = self.fn(*self.args, **self.kwargs)
  File "/home/pzharyuk/Documents/fastAPI-nornir/.venv/lib/python3.8/site-packages/scrapli/channel/sync_channel.py", line 243, in channel_authenticate_ssh
    self._ssh_message_handler(output=authenticate_buf)
  File "/home/pzharyuk/Documents/fastAPI-nornir/.venv/lib/python3.8/site-packages/scrapli/channel/base_channel.py", line 200, in _ssh_message_handler
    raise ScrapliAuthenticationFailed(msg)
scrapli.exceptions.ScrapliAuthenticationFailed: No matching key exchange found for host, their offer: diffie-hellman-group-exchange-sha1,diffie-hellman-group14-sha1

2021-05-31 23:12:08,017 - nornir.core.task -    ERROR -      start() - Host 'RTR2': task 'send_command' failed with traceback:
Traceback (most recent call last):
  File "/home/pzharyuk/Documents/fastAPI-nornir/.venv/lib/python3.8/site-packages/nornir/core/task.py", line 99, in start
    r = self.task(self, **self.params)
  File "/home/pzharyuk/Documents/fastAPI-nornir/.venv/lib/python3.8/site-packages/nornir_scrapli/tasks/send_command.py", line 36, in send_command
    scrapli_conn = task.host.get_connection("scrapli", task.nornir.config)
  File "/home/pzharyuk/Documents/fastAPI-nornir/.venv/lib/python3.8/site-packages/nornir/core/inventory.py", line 494, in get_connection
    self.open_connection(
  File "/home/pzharyuk/Documents/fastAPI-nornir/.venv/lib/python3.8/site-packages/nornir/core/inventory.py", line 546, in open_connection
    conn_obj.open(
  File "/home/pzharyuk/Documents/fastAPI-nornir/.venv/lib/python3.8/site-packages/nornir_scrapli/connection.py", line 93, in open
    connection.open()
  File "/home/pzharyuk/Documents/fastAPI-nornir/.venv/lib/python3.8/site-packages/scrapli/driver/base/sync_driver.py", line 85, in open
    self.channel.channel_authenticate_ssh(
  File "/home/pzharyuk/Documents/fastAPI-nornir/.venv/lib/python3.8/site-packages/scrapli/decorators.py", line 275, in decorate
    return self._multiprocessing_timeout(
  File "/home/pzharyuk/Documents/fastAPI-nornir/.venv/lib/python3.8/site-packages/scrapli/decorators.py", line 336, in _multiprocessing_timeout
    return future.result()
  File "/usr/lib/python3.8/concurrent/futures/_base.py", line 432, in result
    return self.__get_result()
  File "/usr/lib/python3.8/concurrent/futures/_base.py", line 388, in __get_result
    raise self._exception
  File "/usr/lib/python3.8/concurrent/futures/thread.py", line 57, in run
    result = self.fn(*self.args, **self.kwargs)
  File "/home/pzharyuk/Documents/fastAPI-nornir/.venv/lib/python3.8/site-packages/scrapli/channel/sync_channel.py", line 243, in channel_authenticate_ssh
    self._ssh_message_handler(output=authenticate_buf)
  File "/home/pzharyuk/Documents/fastAPI-nornir/.venv/lib/python3.8/site-packages/scrapli/channel/base_channel.py", line 200, in _ssh_message_handler
    raise ScrapliAuthenticationFailed(msg)
scrapli.exceptions.ScrapliAuthenticationFailed: No matching key exchange found for host, their offer: diffie-hellman-group-exchange-sha1,diffie-hellman-group14-sha1

2021-05-31 23:13:10,514 -  nornir.core -     INFO -        run() - Running task 'send_command' with args {'command': 'show run'} on 3 hosts
2021-05-31 23:13:11,438 - nornir.core.task -    ERROR -      start() - Host 'RT31': task 'send_command' failed with traceback:
Traceback (most recent call last):
  File "/home/pzharyuk/Documents/fastAPI-nornir/.venv/lib/python3.8/site-packages/nornir/core/task.py", line 99, in start
    r = self.task(self, **self.params)
  File "/home/pzharyuk/Documents/fastAPI-nornir/.venv/lib/python3.8/site-packages/nornir_scrapli/tasks/send_command.py", line 36, in send_command
    scrapli_conn = task.host.get_connection("scrapli", task.nornir.config)
  File "/home/pzharyuk/Documents/fastAPI-nornir/.venv/lib/python3.8/site-packages/nornir/core/inventory.py", line 494, in get_connection
    self.open_connection(
  File "/home/pzharyuk/Documents/fastAPI-nornir/.venv/lib/python3.8/site-packages/nornir/core/inventory.py", line 546, in open_connection
    conn_obj.open(
  File "/home/pzharyuk/Documents/fastAPI-nornir/.venv/lib/python3.8/site-packages/nornir_scrapli/connection.py", line 93, in open
    connection.open()
  File "/home/pzharyuk/Documents/fastAPI-nornir/.venv/lib/python3.8/site-packages/scrapli/driver/base/sync_driver.py", line 85, in open
    self.channel.channel_authenticate_ssh(
  File "/home/pzharyuk/Documents/fastAPI-nornir/.venv/lib/python3.8/site-packages/scrapli/decorators.py", line 275, in decorate
    return self._multiprocessing_timeout(
  File "/home/pzharyuk/Documents/fastAPI-nornir/.venv/lib/python3.8/site-packages/scrapli/decorators.py", line 336, in _multiprocessing_timeout
    return future.result()
  File "/usr/lib/python3.8/concurrent/futures/_base.py", line 432, in result
    return self.__get_result()
  File "/usr/lib/python3.8/concurrent/futures/_base.py", line 388, in __get_result
    raise self._exception
  File "/usr/lib/python3.8/concurrent/futures/thread.py", line 57, in run
    result = self.fn(*self.args, **self.kwargs)
  File "/home/pzharyuk/Documents/fastAPI-nornir/.venv/lib/python3.8/site-packages/scrapli/channel/sync_channel.py", line 243, in channel_authenticate_ssh
    self._ssh_message_handler(output=authenticate_buf)
  File "/home/pzharyuk/Documents/fastAPI-nornir/.venv/lib/python3.8/site-packages/scrapli/channel/base_channel.py", line 200, in _ssh_message_handler
    raise ScrapliAuthenticationFailed(msg)
scrapli.exceptions.ScrapliAuthenticationFailed: No matching key exchange found for host, their offer: diffie-hellman-group-exchange-sha1,diffie-hellman-group14-sha1

2021-05-31 23:13:11,553 - nornir.core.task -    ERROR -      start() - Host 'RTR2': task 'send_command' failed with traceback:
Traceback (most recent call last):
  File "/home/pzharyuk/Documents/fastAPI-nornir/.venv/lib/python3.8/site-packages/nornir/core/task.py", line 99, in start
    r = self.task(self, **self.params)
  File "/home/pzharyuk/Documents/fastAPI-nornir/.venv/lib/python3.8/site-packages/nornir_scrapli/tasks/send_command.py", line 36, in send_command
    scrapli_conn = task.host.get_connection("scrapli", task.nornir.config)
  File "/home/pzharyuk/Documents/fastAPI-nornir/.venv/lib/python3.8/site-packages/nornir/core/inventory.py", line 494, in get_connection
    self.open_connection(
  File "/home/pzharyuk/Documents/fastAPI-nornir/.venv/lib/python3.8/site-packages/nornir/core/inventory.py", line 546, in open_connection
    conn_obj.open(
  File "/home/pzharyuk/Documents/fastAPI-nornir/.venv/lib/python3.8/site-packages/nornir_scrapli/connection.py", line 93, in open
    connection.open()
  File "/home/pzharyuk/Documents/fastAPI-nornir/.venv/lib/python3.8/site-packages/scrapli/driver/base/sync_driver.py", line 85, in open
    self.channel.channel_authenticate_ssh(
  File "/home/pzharyuk/Documents/fastAPI-nornir/.venv/lib/python3.8/site-packages/scrapli/decorators.py", line 275, in decorate
    return self._multiprocessing_timeout(
  File "/home/pzharyuk/Documents/fastAPI-nornir/.venv/lib/python3.8/site-packages/scrapli/decorators.py", line 336, in _multiprocessing_timeout
    return future.result()
  File "/usr/lib/python3.8/concurrent/futures/_base.py", line 432, in result
    return self.__get_result()
  File "/usr/lib/python3.8/concurrent/futures/_base.py", line 388, in __get_result
    raise self._exception
  File "/usr/lib/python3.8/concurrent/futures/thread.py", line 57, in run
    result = self.fn(*self.args, **self.kwargs)
  File "/home/pzharyuk/Documents/fastAPI-nornir/.venv/lib/python3.8/site-packages/scrapli/channel/sync_channel.py", line 243, in channel_authenticate_ssh
    self._ssh_message_handler(output=authenticate_buf)
  File "/home/pzharyuk/Documents/fastAPI-nornir/.venv/lib/python3.8/site-packages/scrapli/channel/base_channel.py", line 200, in _ssh_message_handler
    raise ScrapliAuthenticationFailed(msg)
scrapli.exceptions.ScrapliAuthenticationFailed: No matching key exchange found for host, their offer: diffie-hellman-group-exchange-sha1,diffie-hellman-group14-sha1

2021-05-31 23:13:11,562 - nornir.core.task -    ERROR -      start() - Host 'RTR1': task 'send_command' failed with traceback:
Traceback (most recent call last):
  File "/home/pzharyuk/Documents/fastAPI-nornir/.venv/lib/python3.8/site-packages/nornir/core/task.py", line 99, in start
    r = self.task(self, **self.params)
  File "/home/pzharyuk/Documents/fastAPI-nornir/.venv/lib/python3.8/site-packages/nornir_scrapli/tasks/send_command.py", line 36, in send_command
    scrapli_conn = task.host.get_connection("scrapli", task.nornir.config)
  File "/home/pzharyuk/Documents/fastAPI-nornir/.venv/lib/python3.8/site-packages/nornir/core/inventory.py", line 494, in get_connection
    self.open_connection(
  File "/home/pzharyuk/Documents/fastAPI-nornir/.venv/lib/python3.8/site-packages/nornir/core/inventory.py", line 546, in open_connection
    conn_obj.open(
  File "/home/pzharyuk/Documents/fastAPI-nornir/.venv/lib/python3.8/site-packages/nornir_scrapli/connection.py", line 93, in open
    connection.open()
  File "/home/pzharyuk/Documents/fastAPI-nornir/.venv/lib/python3.8/site-packages/scrapli/driver/base/sync_driver.py", line 85, in open
    self.channel.channel_authenticate_ssh(
  File "/home/pzharyuk/Documents/fastAPI-nornir/.venv/lib/python3.8/site-packages/scrapli/decorators.py", line 275, in decorate
    return self._multiprocessing_timeout(
  File "/home/pzharyuk/Documents/fastAPI-nornir/.venv/lib/python3.8/site-packages/scrapli/decorators.py", line 336, in _multiprocessing_timeout
    return future.result()
  File "/usr/lib/python3.8/concurrent/futures/_base.py", line 432, in result
    return self.__get_result()
  File "/usr/lib/python3.8/concurrent/futures/_base.py", line 388, in __get_result
    raise self._exception
  File "/usr/lib/python3.8/concurrent/futures/thread.py", line 57, in run
    result = self.fn(*self.args, **self.kwargs)
  File "/home/pzharyuk/Documents/fastAPI-nornir/.venv/lib/python3.8/site-packages/scrapli/channel/sync_channel.py", line 243, in channel_authenticate_ssh
    self._ssh_message_handler(output=authenticate_buf)
  File "/home/pzharyuk/Documents/fastAPI-nornir/.venv/lib/python3.8/site-packages/scrapli/channel/base_channel.py", line 200, in _ssh_message_handler
    raise ScrapliAuthenticationFailed(msg)
scrapli.exceptions.ScrapliAuthenticationFailed: No matching key exchange found for host, their offer: diffie-hellman-group-exchange-sha1,diffie-hellman-group14-sha1

2021-05-31 23:13:23,200 -  nornir.core -     INFO -        run() - Running task 'send_command' with args {'command': 'show version'} on 3 hosts
2021-05-31 23:13:24,252 - nornir.core.task -    ERROR -      start() - Host 'RTR2': task 'send_command' failed with traceback:
Traceback (most recent call last):
  File "/home/pzharyuk/Documents/fastAPI-nornir/.venv/lib/python3.8/site-packages/nornir/core/task.py", line 99, in start
    r = self.task(self, **self.params)
  File "/home/pzharyuk/Documents/fastAPI-nornir/.venv/lib/python3.8/site-packages/nornir_scrapli/tasks/send_command.py", line 36, in send_command
    scrapli_conn = task.host.get_connection("scrapli", task.nornir.config)
  File "/home/pzharyuk/Documents/fastAPI-nornir/.venv/lib/python3.8/site-packages/nornir/core/inventory.py", line 494, in get_connection
    self.open_connection(
  File "/home/pzharyuk/Documents/fastAPI-nornir/.venv/lib/python3.8/site-packages/nornir/core/inventory.py", line 546, in open_connection
    conn_obj.open(
  File "/home/pzharyuk/Documents/fastAPI-nornir/.venv/lib/python3.8/site-packages/nornir_scrapli/connection.py", line 93, in open
    connection.open()
  File "/home/pzharyuk/Documents/fastAPI-nornir/.venv/lib/python3.8/site-packages/scrapli/driver/base/sync_driver.py", line 85, in open
    self.channel.channel_authenticate_ssh(
  File "/home/pzharyuk/Documents/fastAPI-nornir/.venv/lib/python3.8/site-packages/scrapli/decorators.py", line 275, in decorate
    return self._multiprocessing_timeout(
  File "/home/pzharyuk/Documents/fastAPI-nornir/.venv/lib/python3.8/site-packages/scrapli/decorators.py", line 336, in _multiprocessing_timeout
    return future.result()
  File "/usr/lib/python3.8/concurrent/futures/_base.py", line 432, in result
    return self.__get_result()
  File "/usr/lib/python3.8/concurrent/futures/_base.py", line 388, in __get_result
    raise self._exception
  File "/usr/lib/python3.8/concurrent/futures/thread.py", line 57, in run
    result = self.fn(*self.args, **self.kwargs)
  File "/home/pzharyuk/Documents/fastAPI-nornir/.venv/lib/python3.8/site-packages/scrapli/channel/sync_channel.py", line 243, in channel_authenticate_ssh
    self._ssh_message_handler(output=authenticate_buf)
  File "/home/pzharyuk/Documents/fastAPI-nornir/.venv/lib/python3.8/site-packages/scrapli/channel/base_channel.py", line 200, in _ssh_message_handler
    raise ScrapliAuthenticationFailed(msg)
scrapli.exceptions.ScrapliAuthenticationFailed: No matching key exchange found for host, their offer: diffie-hellman-group-exchange-sha1,diffie-hellman-group14-sha1

2021-05-31 23:13:24,337 - nornir.core.task -    ERROR -      start() - Host 'RT31': task 'send_command' failed with traceback:
Traceback (most recent call last):
  File "/home/pzharyuk/Documents/fastAPI-nornir/.venv/lib/python3.8/site-packages/nornir/core/task.py", line 99, in start
    r = self.task(self, **self.params)
  File "/home/pzharyuk/Documents/fastAPI-nornir/.venv/lib/python3.8/site-packages/nornir_scrapli/tasks/send_command.py", line 36, in send_command
    scrapli_conn = task.host.get_connection("scrapli", task.nornir.config)
  File "/home/pzharyuk/Documents/fastAPI-nornir/.venv/lib/python3.8/site-packages/nornir/core/inventory.py", line 494, in get_connection
    self.open_connection(
  File "/home/pzharyuk/Documents/fastAPI-nornir/.venv/lib/python3.8/site-packages/nornir/core/inventory.py", line 546, in open_connection
    conn_obj.open(
  File "/home/pzharyuk/Documents/fastAPI-nornir/.venv/lib/python3.8/site-packages/nornir_scrapli/connection.py", line 93, in open
    connection.open()
  File "/home/pzharyuk/Documents/fastAPI-nornir/.venv/lib/python3.8/site-packages/scrapli/driver/base/sync_driver.py", line 85, in open
    self.channel.channel_authenticate_ssh(
  File "/home/pzharyuk/Documents/fastAPI-nornir/.venv/lib/python3.8/site-packages/scrapli/decorators.py", line 275, in decorate
    return self._multiprocessing_timeout(
  File "/home/pzharyuk/Documents/fastAPI-nornir/.venv/lib/python3.8/site-packages/scrapli/decorators.py", line 336, in _multiprocessing_timeout
    return future.result()
  File "/usr/lib/python3.8/concurrent/futures/_base.py", line 432, in result
    return self.__get_result()
  File "/usr/lib/python3.8/concurrent/futures/_base.py", line 388, in __get_result
    raise self._exception
  File "/usr/lib/python3.8/concurrent/futures/thread.py", line 57, in run
    result = self.fn(*self.args, **self.kwargs)
  File "/home/pzharyuk/Documents/fastAPI-nornir/.venv/lib/python3.8/site-packages/scrapli/channel/sync_channel.py", line 243, in channel_authenticate_ssh
    self._ssh_message_handler(output=authenticate_buf)
  File "/home/pzharyuk/Documents/fastAPI-nornir/.venv/lib/python3.8/site-packages/scrapli/channel/base_channel.py", line 200, in _ssh_message_handler
    raise ScrapliAuthenticationFailed(msg)
scrapli.exceptions.ScrapliAuthenticationFailed: No matching key exchange found for host, their offer: diffie-hellman-group-exchange-sha1,diffie-hellman-group14-sha1

2021-05-31 23:13:24,344 - nornir.core.task -    ERROR -      start() - Host 'RTR1': task 'send_command' failed with traceback:
Traceback (most recent call last):
  File "/home/pzharyuk/Documents/fastAPI-nornir/.venv/lib/python3.8/site-packages/nornir/core/task.py", line 99, in start
    r = self.task(self, **self.params)
  File "/home/pzharyuk/Documents/fastAPI-nornir/.venv/lib/python3.8/site-packages/nornir_scrapli/tasks/send_command.py", line 36, in send_command
    scrapli_conn = task.host.get_connection("scrapli", task.nornir.config)
  File "/home/pzharyuk/Documents/fastAPI-nornir/.venv/lib/python3.8/site-packages/nornir/core/inventory.py", line 494, in get_connection
    self.open_connection(
  File "/home/pzharyuk/Documents/fastAPI-nornir/.venv/lib/python3.8/site-packages/nornir/core/inventory.py", line 546, in open_connection
    conn_obj.open(
  File "/home/pzharyuk/Documents/fastAPI-nornir/.venv/lib/python3.8/site-packages/nornir_scrapli/connection.py", line 93, in open
    connection.open()
  File "/home/pzharyuk/Documents/fastAPI-nornir/.venv/lib/python3.8/site-packages/scrapli/driver/base/sync_driver.py", line 85, in open
    self.channel.channel_authenticate_ssh(
  File "/home/pzharyuk/Documents/fastAPI-nornir/.venv/lib/python3.8/site-packages/scrapli/decorators.py", line 275, in decorate
    return self._multiprocessing_timeout(
  File "/home/pzharyuk/Documents/fastAPI-nornir/.venv/lib/python3.8/site-packages/scrapli/decorators.py", line 336, in _multiprocessing_timeout
    return future.result()
  File "/usr/lib/python3.8/concurrent/futures/_base.py", line 432, in result
    return self.__get_result()
  File "/usr/lib/python3.8/concurrent/futures/_base.py", line 388, in __get_result
    raise self._exception
  File "/usr/lib/python3.8/concurrent/futures/thread.py", line 57, in run
    result = self.fn(*self.args, **self.kwargs)
  File "/home/pzharyuk/Documents/fastAPI-nornir/.venv/lib/python3.8/site-packages/scrapli/channel/sync_channel.py", line 243, in channel_authenticate_ssh
    self._ssh_message_handler(output=authenticate_buf)
  File "/home/pzharyuk/Documents/fastAPI-nornir/.venv/lib/python3.8/site-packages/scrapli/channel/base_channel.py", line 200, in _ssh_message_handler
    raise ScrapliAuthenticationFailed(msg)
scrapli.exceptions.ScrapliAuthenticationFailed: No matching key exchange found for host, their offer: diffie-hellman-group-exchange-sha1,diffie-hellman-group14-sha1

2021-05-31 23:15:19,542 -  nornir.core -     INFO -        run() - Running task 'send_command' with args {'command': 'show version'} on 3 hosts
2021-05-31 23:15:20,578 - nornir.core.task -    ERROR -      start() - Host 'RT31': task 'send_command' failed with traceback:
Traceback (most recent call last):
  File "/home/pzharyuk/Documents/fastAPI-nornir/.venv/lib/python3.8/site-packages/nornir/core/task.py", line 99, in start
    r = self.task(self, **self.params)
  File "/home/pzharyuk/Documents/fastAPI-nornir/.venv/lib/python3.8/site-packages/nornir_scrapli/tasks/send_command.py", line 36, in send_command
    scrapli_conn = task.host.get_connection("scrapli", task.nornir.config)
  File "/home/pzharyuk/Documents/fastAPI-nornir/.venv/lib/python3.8/site-packages/nornir/core/inventory.py", line 494, in get_connection
    self.open_connection(
  File "/home/pzharyuk/Documents/fastAPI-nornir/.venv/lib/python3.8/site-packages/nornir/core/inventory.py", line 546, in open_connection
    conn_obj.open(
  File "/home/pzharyuk/Documents/fastAPI-nornir/.venv/lib/python3.8/site-packages/nornir_scrapli/connection.py", line 93, in open
    connection.open()
  File "/home/pzharyuk/Documents/fastAPI-nornir/.venv/lib/python3.8/site-packages/scrapli/driver/base/sync_driver.py", line 85, in open
    self.channel.channel_authenticate_ssh(
  File "/home/pzharyuk/Documents/fastAPI-nornir/.venv/lib/python3.8/site-packages/scrapli/decorators.py", line 275, in decorate
    return self._multiprocessing_timeout(
  File "/home/pzharyuk/Documents/fastAPI-nornir/.venv/lib/python3.8/site-packages/scrapli/decorators.py", line 336, in _multiprocessing_timeout
    return future.result()
  File "/usr/lib/python3.8/concurrent/futures/_base.py", line 432, in result
    return self.__get_result()
  File "/usr/lib/python3.8/concurrent/futures/_base.py", line 388, in __get_result
    raise self._exception
  File "/usr/lib/python3.8/concurrent/futures/thread.py", line 57, in run
    result = self.fn(*self.args, **self.kwargs)
  File "/home/pzharyuk/Documents/fastAPI-nornir/.venv/lib/python3.8/site-packages/scrapli/channel/sync_channel.py", line 243, in channel_authenticate_ssh
    self._ssh_message_handler(output=authenticate_buf)
  File "/home/pzharyuk/Documents/fastAPI-nornir/.venv/lib/python3.8/site-packages/scrapli/channel/base_channel.py", line 200, in _ssh_message_handler
    raise ScrapliAuthenticationFailed(msg)
scrapli.exceptions.ScrapliAuthenticationFailed: No matching key exchange found for host, their offer: diffie-hellman-group-exchange-sha1,diffie-hellman-group14-sha1

2021-05-31 23:15:20,652 - nornir.core.task -    ERROR -      start() - Host 'RTR1': task 'send_command' failed with traceback:
Traceback (most recent call last):
  File "/home/pzharyuk/Documents/fastAPI-nornir/.venv/lib/python3.8/site-packages/nornir/core/task.py", line 99, in start
    r = self.task(self, **self.params)
  File "/home/pzharyuk/Documents/fastAPI-nornir/.venv/lib/python3.8/site-packages/nornir_scrapli/tasks/send_command.py", line 36, in send_command
    scrapli_conn = task.host.get_connection("scrapli", task.nornir.config)
  File "/home/pzharyuk/Documents/fastAPI-nornir/.venv/lib/python3.8/site-packages/nornir/core/inventory.py", line 494, in get_connection
    self.open_connection(
  File "/home/pzharyuk/Documents/fastAPI-nornir/.venv/lib/python3.8/site-packages/nornir/core/inventory.py", line 546, in open_connection
    conn_obj.open(
  File "/home/pzharyuk/Documents/fastAPI-nornir/.venv/lib/python3.8/site-packages/nornir_scrapli/connection.py", line 93, in open
    connection.open()
  File "/home/pzharyuk/Documents/fastAPI-nornir/.venv/lib/python3.8/site-packages/scrapli/driver/base/sync_driver.py", line 85, in open
    self.channel.channel_authenticate_ssh(
  File "/home/pzharyuk/Documents/fastAPI-nornir/.venv/lib/python3.8/site-packages/scrapli/decorators.py", line 275, in decorate
    return self._multiprocessing_timeout(
  File "/home/pzharyuk/Documents/fastAPI-nornir/.venv/lib/python3.8/site-packages/scrapli/decorators.py", line 336, in _multiprocessing_timeout
    return future.result()
  File "/usr/lib/python3.8/concurrent/futures/_base.py", line 432, in result
    return self.__get_result()
  File "/usr/lib/python3.8/concurrent/futures/_base.py", line 388, in __get_result
    raise self._exception
  File "/usr/lib/python3.8/concurrent/futures/thread.py", line 57, in run
    result = self.fn(*self.args, **self.kwargs)
  File "/home/pzharyuk/Documents/fastAPI-nornir/.venv/lib/python3.8/site-packages/scrapli/channel/sync_channel.py", line 243, in channel_authenticate_ssh
    self._ssh_message_handler(output=authenticate_buf)
  File "/home/pzharyuk/Documents/fastAPI-nornir/.venv/lib/python3.8/site-packages/scrapli/channel/base_channel.py", line 200, in _ssh_message_handler
    raise ScrapliAuthenticationFailed(msg)
scrapli.exceptions.ScrapliAuthenticationFailed: No matching key exchange found for host, their offer: diffie-hellman-group-exchange-sha1,diffie-hellman-group14-sha1

2021-05-31 23:15:20,720 - nornir.core.task -    ERROR -      start() - Host 'RTR2': task 'send_command' failed with traceback:
Traceback (most recent call last):
  File "/home/pzharyuk/Documents/fastAPI-nornir/.venv/lib/python3.8/site-packages/nornir/core/task.py", line 99, in start
    r = self.task(self, **self.params)
  File "/home/pzharyuk/Documents/fastAPI-nornir/.venv/lib/python3.8/site-packages/nornir_scrapli/tasks/send_command.py", line 36, in send_command
    scrapli_conn = task.host.get_connection("scrapli", task.nornir.config)
  File "/home/pzharyuk/Documents/fastAPI-nornir/.venv/lib/python3.8/site-packages/nornir/core/inventory.py", line 494, in get_connection
    self.open_connection(
  File "/home/pzharyuk/Documents/fastAPI-nornir/.venv/lib/python3.8/site-packages/nornir/core/inventory.py", line 546, in open_connection
    conn_obj.open(
  File "/home/pzharyuk/Documents/fastAPI-nornir/.venv/lib/python3.8/site-packages/nornir_scrapli/connection.py", line 93, in open
    connection.open()
  File "/home/pzharyuk/Documents/fastAPI-nornir/.venv/lib/python3.8/site-packages/scrapli/driver/base/sync_driver.py", line 85, in open
    self.channel.channel_authenticate_ssh(
  File "/home/pzharyuk/Documents/fastAPI-nornir/.venv/lib/python3.8/site-packages/scrapli/decorators.py", line 275, in decorate
    return self._multiprocessing_timeout(
  File "/home/pzharyuk/Documents/fastAPI-nornir/.venv/lib/python3.8/site-packages/scrapli/decorators.py", line 336, in _multiprocessing_timeout
    return future.result()
  File "/usr/lib/python3.8/concurrent/futures/_base.py", line 432, in result
    return self.__get_result()
  File "/usr/lib/python3.8/concurrent/futures/_base.py", line 388, in __get_result
    raise self._exception
  File "/usr/lib/python3.8/concurrent/futures/thread.py", line 57, in run
    result = self.fn(*self.args, **self.kwargs)
  File "/home/pzharyuk/Documents/fastAPI-nornir/.venv/lib/python3.8/site-packages/scrapli/channel/sync_channel.py", line 243, in channel_authenticate_ssh
    self._ssh_message_handler(output=authenticate_buf)
  File "/home/pzharyuk/Documents/fastAPI-nornir/.venv/lib/python3.8/site-packages/scrapli/channel/base_channel.py", line 200, in _ssh_message_handler
    raise ScrapliAuthenticationFailed(msg)
scrapli.exceptions.ScrapliAuthenticationFailed: No matching key exchange found for host, their offer: diffie-hellman-group-exchange-sha1,diffie-hellman-group14-sha1

2021-05-31 23:15:43,963 -  nornir.core -     INFO -        run() - Running task 'send_command' with args {'command': 'show version'} on 3 hosts
2021-05-31 23:15:45,058 - nornir.core.task -    ERROR -      start() - Host 'RTR1': task 'send_command' failed with traceback:
Traceback (most recent call last):
  File "/home/pzharyuk/Documents/fastAPI-nornir/.venv/lib/python3.8/site-packages/nornir/core/task.py", line 99, in start
    r = self.task(self, **self.params)
  File "/home/pzharyuk/Documents/fastAPI-nornir/.venv/lib/python3.8/site-packages/nornir_scrapli/tasks/send_command.py", line 36, in send_command
    scrapli_conn = task.host.get_connection("scrapli", task.nornir.config)
  File "/home/pzharyuk/Documents/fastAPI-nornir/.venv/lib/python3.8/site-packages/nornir/core/inventory.py", line 494, in get_connection
    self.open_connection(
  File "/home/pzharyuk/Documents/fastAPI-nornir/.venv/lib/python3.8/site-packages/nornir/core/inventory.py", line 546, in open_connection
    conn_obj.open(
  File "/home/pzharyuk/Documents/fastAPI-nornir/.venv/lib/python3.8/site-packages/nornir_scrapli/connection.py", line 93, in open
    connection.open()
  File "/home/pzharyuk/Documents/fastAPI-nornir/.venv/lib/python3.8/site-packages/scrapli/driver/base/sync_driver.py", line 85, in open
    self.channel.channel_authenticate_ssh(
  File "/home/pzharyuk/Documents/fastAPI-nornir/.venv/lib/python3.8/site-packages/scrapli/decorators.py", line 275, in decorate
    return self._multiprocessing_timeout(
  File "/home/pzharyuk/Documents/fastAPI-nornir/.venv/lib/python3.8/site-packages/scrapli/decorators.py", line 336, in _multiprocessing_timeout
    return future.result()
  File "/usr/lib/python3.8/concurrent/futures/_base.py", line 432, in result
    return self.__get_result()
  File "/usr/lib/python3.8/concurrent/futures/_base.py", line 388, in __get_result
    raise self._exception
  File "/usr/lib/python3.8/concurrent/futures/thread.py", line 57, in run
    result = self.fn(*self.args, **self.kwargs)
  File "/home/pzharyuk/Documents/fastAPI-nornir/.venv/lib/python3.8/site-packages/scrapli/channel/sync_channel.py", line 243, in channel_authenticate_ssh
    self._ssh_message_handler(output=authenticate_buf)
  File "/home/pzharyuk/Documents/fastAPI-nornir/.venv/lib/python3.8/site-packages/scrapli/channel/base_channel.py", line 200, in _ssh_message_handler
    raise ScrapliAuthenticationFailed(msg)
scrapli.exceptions.ScrapliAuthenticationFailed: No matching key exchange found for host, their offer: diffie-hellman-group-exchange-sha1,diffie-hellman-group14-sha1

2021-05-31 23:15:45,092 - nornir.core.task -    ERROR -      start() - Host 'RTR2': task 'send_command' failed with traceback:
Traceback (most recent call last):
  File "/home/pzharyuk/Documents/fastAPI-nornir/.venv/lib/python3.8/site-packages/nornir/core/task.py", line 99, in start
    r = self.task(self, **self.params)
  File "/home/pzharyuk/Documents/fastAPI-nornir/.venv/lib/python3.8/site-packages/nornir_scrapli/tasks/send_command.py", line 36, in send_command
    scrapli_conn = task.host.get_connection("scrapli", task.nornir.config)
  File "/home/pzharyuk/Documents/fastAPI-nornir/.venv/lib/python3.8/site-packages/nornir/core/inventory.py", line 494, in get_connection
    self.open_connection(
  File "/home/pzharyuk/Documents/fastAPI-nornir/.venv/lib/python3.8/site-packages/nornir/core/inventory.py", line 546, in open_connection
    conn_obj.open(
  File "/home/pzharyuk/Documents/fastAPI-nornir/.venv/lib/python3.8/site-packages/nornir_scrapli/connection.py", line 93, in open
    connection.open()
  File "/home/pzharyuk/Documents/fastAPI-nornir/.venv/lib/python3.8/site-packages/scrapli/driver/base/sync_driver.py", line 85, in open
    self.channel.channel_authenticate_ssh(
  File "/home/pzharyuk/Documents/fastAPI-nornir/.venv/lib/python3.8/site-packages/scrapli/decorators.py", line 275, in decorate
    return self._multiprocessing_timeout(
  File "/home/pzharyuk/Documents/fastAPI-nornir/.venv/lib/python3.8/site-packages/scrapli/decorators.py", line 336, in _multiprocessing_timeout
    return future.result()
  File "/usr/lib/python3.8/concurrent/futures/_base.py", line 432, in result
    return self.__get_result()
  File "/usr/lib/python3.8/concurrent/futures/_base.py", line 388, in __get_result
    raise self._exception
  File "/usr/lib/python3.8/concurrent/futures/thread.py", line 57, in run
    result = self.fn(*self.args, **self.kwargs)
  File "/home/pzharyuk/Documents/fastAPI-nornir/.venv/lib/python3.8/site-packages/scrapli/channel/sync_channel.py", line 243, in channel_authenticate_ssh
    self._ssh_message_handler(output=authenticate_buf)
  File "/home/pzharyuk/Documents/fastAPI-nornir/.venv/lib/python3.8/site-packages/scrapli/channel/base_channel.py", line 200, in _ssh_message_handler
    raise ScrapliAuthenticationFailed(msg)
scrapli.exceptions.ScrapliAuthenticationFailed: No matching key exchange found for host, their offer: diffie-hellman-group-exchange-sha1,diffie-hellman-group14-sha1

2021-05-31 23:15:45,167 - nornir.core.task -    ERROR -      start() - Host 'RT31': task 'send_command' failed with traceback:
Traceback (most recent call last):
  File "/home/pzharyuk/Documents/fastAPI-nornir/.venv/lib/python3.8/site-packages/nornir/core/task.py", line 99, in start
    r = self.task(self, **self.params)
  File "/home/pzharyuk/Documents/fastAPI-nornir/.venv/lib/python3.8/site-packages/nornir_scrapli/tasks/send_command.py", line 36, in send_command
    scrapli_conn = task.host.get_connection("scrapli", task.nornir.config)
  File "/home/pzharyuk/Documents/fastAPI-nornir/.venv/lib/python3.8/site-packages/nornir/core/inventory.py", line 494, in get_connection
    self.open_connection(
  File "/home/pzharyuk/Documents/fastAPI-nornir/.venv/lib/python3.8/site-packages/nornir/core/inventory.py", line 546, in open_connection
    conn_obj.open(
  File "/home/pzharyuk/Documents/fastAPI-nornir/.venv/lib/python3.8/site-packages/nornir_scrapli/connection.py", line 93, in open
    connection.open()
  File "/home/pzharyuk/Documents/fastAPI-nornir/.venv/lib/python3.8/site-packages/scrapli/driver/base/sync_driver.py", line 85, in open
    self.channel.channel_authenticate_ssh(
  File "/home/pzharyuk/Documents/fastAPI-nornir/.venv/lib/python3.8/site-packages/scrapli/decorators.py", line 275, in decorate
    return self._multiprocessing_timeout(
  File "/home/pzharyuk/Documents/fastAPI-nornir/.venv/lib/python3.8/site-packages/scrapli/decorators.py", line 336, in _multiprocessing_timeout
    return future.result()
  File "/usr/lib/python3.8/concurrent/futures/_base.py", line 432, in result
    return self.__get_result()
  File "/usr/lib/python3.8/concurrent/futures/_base.py", line 388, in __get_result
    raise self._exception
  File "/usr/lib/python3.8/concurrent/futures/thread.py", line 57, in run
    result = self.fn(*self.args, **self.kwargs)
  File "/home/pzharyuk/Documents/fastAPI-nornir/.venv/lib/python3.8/site-packages/scrapli/channel/sync_channel.py", line 243, in channel_authenticate_ssh
    self._ssh_message_handler(output=authenticate_buf)
  File "/home/pzharyuk/Documents/fastAPI-nornir/.venv/lib/python3.8/site-packages/scrapli/channel/base_channel.py", line 200, in _ssh_message_handler
    raise ScrapliAuthenticationFailed(msg)
scrapli.exceptions.ScrapliAuthenticationFailed: No matching key exchange found for host, their offer: diffie-hellman-group-exchange-sha1,diffie-hellman-group14-sha1

2021-05-31 23:15:58,447 -  nornir.core -     INFO -        run() - Running task 'send_command' with args {'command': 'show run'} on 3 hosts
2021-05-31 23:15:59,583 - nornir.core.task -    ERROR -      start() - Host 'RTR1': task 'send_command' failed with traceback:
Traceback (most recent call last):
  File "/home/pzharyuk/Documents/fastAPI-nornir/.venv/lib/python3.8/site-packages/nornir/core/task.py", line 99, in start
    r = self.task(self, **self.params)
  File "/home/pzharyuk/Documents/fastAPI-nornir/.venv/lib/python3.8/site-packages/nornir_scrapli/tasks/send_command.py", line 36, in send_command
    scrapli_conn = task.host.get_connection("scrapli", task.nornir.config)
  File "/home/pzharyuk/Documents/fastAPI-nornir/.venv/lib/python3.8/site-packages/nornir/core/inventory.py", line 494, in get_connection
    self.open_connection(
  File "/home/pzharyuk/Documents/fastAPI-nornir/.venv/lib/python3.8/site-packages/nornir/core/inventory.py", line 546, in open_connection
    conn_obj.open(
  File "/home/pzharyuk/Documents/fastAPI-nornir/.venv/lib/python3.8/site-packages/nornir_scrapli/connection.py", line 93, in open
    connection.open()
  File "/home/pzharyuk/Documents/fastAPI-nornir/.venv/lib/python3.8/site-packages/scrapli/driver/base/sync_driver.py", line 85, in open
    self.channel.channel_authenticate_ssh(
  File "/home/pzharyuk/Documents/fastAPI-nornir/.venv/lib/python3.8/site-packages/scrapli/decorators.py", line 275, in decorate
    return self._multiprocessing_timeout(
  File "/home/pzharyuk/Documents/fastAPI-nornir/.venv/lib/python3.8/site-packages/scrapli/decorators.py", line 336, in _multiprocessing_timeout
    return future.result()
  File "/usr/lib/python3.8/concurrent/futures/_base.py", line 432, in result
    return self.__get_result()
  File "/usr/lib/python3.8/concurrent/futures/_base.py", line 388, in __get_result
    raise self._exception
  File "/usr/lib/python3.8/concurrent/futures/thread.py", line 57, in run
    result = self.fn(*self.args, **self.kwargs)
  File "/home/pzharyuk/Documents/fastAPI-nornir/.venv/lib/python3.8/site-packages/scrapli/channel/sync_channel.py", line 243, in channel_authenticate_ssh
    self._ssh_message_handler(output=authenticate_buf)
  File "/home/pzharyuk/Documents/fastAPI-nornir/.venv/lib/python3.8/site-packages/scrapli/channel/base_channel.py", line 200, in _ssh_message_handler
    raise ScrapliAuthenticationFailed(msg)
scrapli.exceptions.ScrapliAuthenticationFailed: No matching key exchange found for host, their offer: diffie-hellman-group-exchange-sha1,diffie-hellman-group14-sha1

2021-05-31 23:15:59,586 - nornir.core.task -    ERROR -      start() - Host 'RTR2': task 'send_command' failed with traceback:
Traceback (most recent call last):
  File "/home/pzharyuk/Documents/fastAPI-nornir/.venv/lib/python3.8/site-packages/nornir/core/task.py", line 99, in start
    r = self.task(self, **self.params)
  File "/home/pzharyuk/Documents/fastAPI-nornir/.venv/lib/python3.8/site-packages/nornir_scrapli/tasks/send_command.py", line 36, in send_command
    scrapli_conn = task.host.get_connection("scrapli", task.nornir.config)
  File "/home/pzharyuk/Documents/fastAPI-nornir/.venv/lib/python3.8/site-packages/nornir/core/inventory.py", line 494, in get_connection
    self.open_connection(
  File "/home/pzharyuk/Documents/fastAPI-nornir/.venv/lib/python3.8/site-packages/nornir/core/inventory.py", line 546, in open_connection
    conn_obj.open(
  File "/home/pzharyuk/Documents/fastAPI-nornir/.venv/lib/python3.8/site-packages/nornir_scrapli/connection.py", line 93, in open
    connection.open()
  File "/home/pzharyuk/Documents/fastAPI-nornir/.venv/lib/python3.8/site-packages/scrapli/driver/base/sync_driver.py", line 85, in open
    self.channel.channel_authenticate_ssh(
  File "/home/pzharyuk/Documents/fastAPI-nornir/.venv/lib/python3.8/site-packages/scrapli/decorators.py", line 275, in decorate
    return self._multiprocessing_timeout(
  File "/home/pzharyuk/Documents/fastAPI-nornir/.venv/lib/python3.8/site-packages/scrapli/decorators.py", line 336, in _multiprocessing_timeout
    return future.result()
  File "/usr/lib/python3.8/concurrent/futures/_base.py", line 432, in result
    return self.__get_result()
  File "/usr/lib/python3.8/concurrent/futures/_base.py", line 388, in __get_result
    raise self._exception
  File "/usr/lib/python3.8/concurrent/futures/thread.py", line 57, in run
    result = self.fn(*self.args, **self.kwargs)
  File "/home/pzharyuk/Documents/fastAPI-nornir/.venv/lib/python3.8/site-packages/scrapli/channel/sync_channel.py", line 243, in channel_authenticate_ssh
    self._ssh_message_handler(output=authenticate_buf)
  File "/home/pzharyuk/Documents/fastAPI-nornir/.venv/lib/python3.8/site-packages/scrapli/channel/base_channel.py", line 200, in _ssh_message_handler
    raise ScrapliAuthenticationFailed(msg)
scrapli.exceptions.ScrapliAuthenticationFailed: No matching key exchange found for host, their offer: diffie-hellman-group-exchange-sha1,diffie-hellman-group14-sha1

2021-05-31 23:15:59,638 - nornir.core.task -    ERROR -      start() - Host 'RT31': task 'send_command' failed with traceback:
Traceback (most recent call last):
  File "/home/pzharyuk/Documents/fastAPI-nornir/.venv/lib/python3.8/site-packages/nornir/core/task.py", line 99, in start
    r = self.task(self, **self.params)
  File "/home/pzharyuk/Documents/fastAPI-nornir/.venv/lib/python3.8/site-packages/nornir_scrapli/tasks/send_command.py", line 36, in send_command
    scrapli_conn = task.host.get_connection("scrapli", task.nornir.config)
  File "/home/pzharyuk/Documents/fastAPI-nornir/.venv/lib/python3.8/site-packages/nornir/core/inventory.py", line 494, in get_connection
    self.open_connection(
  File "/home/pzharyuk/Documents/fastAPI-nornir/.venv/lib/python3.8/site-packages/nornir/core/inventory.py", line 546, in open_connection
    conn_obj.open(
  File "/home/pzharyuk/Documents/fastAPI-nornir/.venv/lib/python3.8/site-packages/nornir_scrapli/connection.py", line 93, in open
    connection.open()
  File "/home/pzharyuk/Documents/fastAPI-nornir/.venv/lib/python3.8/site-packages/scrapli/driver/base/sync_driver.py", line 85, in open
    self.channel.channel_authenticate_ssh(
  File "/home/pzharyuk/Documents/fastAPI-nornir/.venv/lib/python3.8/site-packages/scrapli/decorators.py", line 275, in decorate
    return self._multiprocessing_timeout(
  File "/home/pzharyuk/Documents/fastAPI-nornir/.venv/lib/python3.8/site-packages/scrapli/decorators.py", line 336, in _multiprocessing_timeout
    return future.result()
  File "/usr/lib/python3.8/concurrent/futures/_base.py", line 432, in result
    return self.__get_result()
  File "/usr/lib/python3.8/concurrent/futures/_base.py", line 388, in __get_result
    raise self._exception
  File "/usr/lib/python3.8/concurrent/futures/thread.py", line 57, in run
    result = self.fn(*self.args, **self.kwargs)
  File "/home/pzharyuk/Documents/fastAPI-nornir/.venv/lib/python3.8/site-packages/scrapli/channel/sync_channel.py", line 243, in channel_authenticate_ssh
    self._ssh_message_handler(output=authenticate_buf)
  File "/home/pzharyuk/Documents/fastAPI-nornir/.venv/lib/python3.8/site-packages/scrapli/channel/base_channel.py", line 200, in _ssh_message_handler
    raise ScrapliAuthenticationFailed(msg)
scrapli.exceptions.ScrapliAuthenticationFailed: No matching key exchange found for host, their offer: diffie-hellman-group-exchange-sha1,diffie-hellman-group14-sha1

2021-05-31 23:16:29,722 -  nornir.core -     INFO -        run() - Running task 'send_command' with args {'command': 'show run'} on 3 hosts
2021-05-31 23:16:30,668 - nornir.core.task -    ERROR -      start() - Host 'RTR2': task 'send_command' failed with traceback:
Traceback (most recent call last):
  File "/home/pzharyuk/Documents/fastAPI-nornir/.venv/lib/python3.8/site-packages/nornir/core/task.py", line 99, in start
    r = self.task(self, **self.params)
  File "/home/pzharyuk/Documents/fastAPI-nornir/.venv/lib/python3.8/site-packages/nornir_scrapli/tasks/send_command.py", line 36, in send_command
    scrapli_conn = task.host.get_connection("scrapli", task.nornir.config)
  File "/home/pzharyuk/Documents/fastAPI-nornir/.venv/lib/python3.8/site-packages/nornir/core/inventory.py", line 494, in get_connection
    self.open_connection(
  File "/home/pzharyuk/Documents/fastAPI-nornir/.venv/lib/python3.8/site-packages/nornir/core/inventory.py", line 546, in open_connection
    conn_obj.open(
  File "/home/pzharyuk/Documents/fastAPI-nornir/.venv/lib/python3.8/site-packages/nornir_scrapli/connection.py", line 93, in open
    connection.open()
  File "/home/pzharyuk/Documents/fastAPI-nornir/.venv/lib/python3.8/site-packages/scrapli/driver/base/sync_driver.py", line 85, in open
    self.channel.channel_authenticate_ssh(
  File "/home/pzharyuk/Documents/fastAPI-nornir/.venv/lib/python3.8/site-packages/scrapli/decorators.py", line 275, in decorate
    return self._multiprocessing_timeout(
  File "/home/pzharyuk/Documents/fastAPI-nornir/.venv/lib/python3.8/site-packages/scrapli/decorators.py", line 336, in _multiprocessing_timeout
    return future.result()
  File "/usr/lib/python3.8/concurrent/futures/_base.py", line 432, in result
    return self.__get_result()
  File "/usr/lib/python3.8/concurrent/futures/_base.py", line 388, in __get_result
    raise self._exception
  File "/usr/lib/python3.8/concurrent/futures/thread.py", line 57, in run
    result = self.fn(*self.args, **self.kwargs)
  File "/home/pzharyuk/Documents/fastAPI-nornir/.venv/lib/python3.8/site-packages/scrapli/channel/sync_channel.py", line 243, in channel_authenticate_ssh
    self._ssh_message_handler(output=authenticate_buf)
  File "/home/pzharyuk/Documents/fastAPI-nornir/.venv/lib/python3.8/site-packages/scrapli/channel/base_channel.py", line 200, in _ssh_message_handler
    raise ScrapliAuthenticationFailed(msg)
scrapli.exceptions.ScrapliAuthenticationFailed: No matching key exchange found for host, their offer: diffie-hellman-group-exchange-sha1,diffie-hellman-group14-sha1

2021-05-31 23:16:30,727 - nornir.core.task -    ERROR -      start() - Host 'RTR1': task 'send_command' failed with traceback:
Traceback (most recent call last):
  File "/home/pzharyuk/Documents/fastAPI-nornir/.venv/lib/python3.8/site-packages/nornir/core/task.py", line 99, in start
    r = self.task(self, **self.params)
  File "/home/pzharyuk/Documents/fastAPI-nornir/.venv/lib/python3.8/site-packages/nornir_scrapli/tasks/send_command.py", line 36, in send_command
    scrapli_conn = task.host.get_connection("scrapli", task.nornir.config)
  File "/home/pzharyuk/Documents/fastAPI-nornir/.venv/lib/python3.8/site-packages/nornir/core/inventory.py", line 494, in get_connection
    self.open_connection(
  File "/home/pzharyuk/Documents/fastAPI-nornir/.venv/lib/python3.8/site-packages/nornir/core/inventory.py", line 546, in open_connection
    conn_obj.open(
  File "/home/pzharyuk/Documents/fastAPI-nornir/.venv/lib/python3.8/site-packages/nornir_scrapli/connection.py", line 93, in open
    connection.open()
  File "/home/pzharyuk/Documents/fastAPI-nornir/.venv/lib/python3.8/site-packages/scrapli/driver/base/sync_driver.py", line 85, in open
    self.channel.channel_authenticate_ssh(
  File "/home/pzharyuk/Documents/fastAPI-nornir/.venv/lib/python3.8/site-packages/scrapli/decorators.py", line 275, in decorate
    return self._multiprocessing_timeout(
  File "/home/pzharyuk/Documents/fastAPI-nornir/.venv/lib/python3.8/site-packages/scrapli/decorators.py", line 336, in _multiprocessing_timeout
    return future.result()
  File "/usr/lib/python3.8/concurrent/futures/_base.py", line 432, in result
    return self.__get_result()
  File "/usr/lib/python3.8/concurrent/futures/_base.py", line 388, in __get_result
    raise self._exception
  File "/usr/lib/python3.8/concurrent/futures/thread.py", line 57, in run
    result = self.fn(*self.args, **self.kwargs)
  File "/home/pzharyuk/Documents/fastAPI-nornir/.venv/lib/python3.8/site-packages/scrapli/channel/sync_channel.py", line 243, in channel_authenticate_ssh
    self._ssh_message_handler(output=authenticate_buf)
  File "/home/pzharyuk/Documents/fastAPI-nornir/.venv/lib/python3.8/site-packages/scrapli/channel/base_channel.py", line 200, in _ssh_message_handler
    raise ScrapliAuthenticationFailed(msg)
scrapli.exceptions.ScrapliAuthenticationFailed: No matching key exchange found for host, their offer: diffie-hellman-group-exchange-sha1,diffie-hellman-group14-sha1

2021-05-31 23:16:30,854 - nornir.core.task -    ERROR -      start() - Host 'RT31': task 'send_command' failed with traceback:
Traceback (most recent call last):
  File "/home/pzharyuk/Documents/fastAPI-nornir/.venv/lib/python3.8/site-packages/nornir/core/task.py", line 99, in start
    r = self.task(self, **self.params)
  File "/home/pzharyuk/Documents/fastAPI-nornir/.venv/lib/python3.8/site-packages/nornir_scrapli/tasks/send_command.py", line 36, in send_command
    scrapli_conn = task.host.get_connection("scrapli", task.nornir.config)
  File "/home/pzharyuk/Documents/fastAPI-nornir/.venv/lib/python3.8/site-packages/nornir/core/inventory.py", line 494, in get_connection
    self.open_connection(
  File "/home/pzharyuk/Documents/fastAPI-nornir/.venv/lib/python3.8/site-packages/nornir/core/inventory.py", line 546, in open_connection
    conn_obj.open(
  File "/home/pzharyuk/Documents/fastAPI-nornir/.venv/lib/python3.8/site-packages/nornir_scrapli/connection.py", line 93, in open
    connection.open()
  File "/home/pzharyuk/Documents/fastAPI-nornir/.venv/lib/python3.8/site-packages/scrapli/driver/base/sync_driver.py", line 85, in open
    self.channel.channel_authenticate_ssh(
  File "/home/pzharyuk/Documents/fastAPI-nornir/.venv/lib/python3.8/site-packages/scrapli/decorators.py", line 275, in decorate
    return self._multiprocessing_timeout(
  File "/home/pzharyuk/Documents/fastAPI-nornir/.venv/lib/python3.8/site-packages/scrapli/decorators.py", line 336, in _multiprocessing_timeout
    return future.result()
  File "/usr/lib/python3.8/concurrent/futures/_base.py", line 432, in result
    return self.__get_result()
  File "/usr/lib/python3.8/concurrent/futures/_base.py", line 388, in __get_result
    raise self._exception
  File "/usr/lib/python3.8/concurrent/futures/thread.py", line 57, in run
    result = self.fn(*self.args, **self.kwargs)
  File "/home/pzharyuk/Documents/fastAPI-nornir/.venv/lib/python3.8/site-packages/scrapli/channel/sync_channel.py", line 243, in channel_authenticate_ssh
    self._ssh_message_handler(output=authenticate_buf)
  File "/home/pzharyuk/Documents/fastAPI-nornir/.venv/lib/python3.8/site-packages/scrapli/channel/base_channel.py", line 200, in _ssh_message_handler
    raise ScrapliAuthenticationFailed(msg)
scrapli.exceptions.ScrapliAuthenticationFailed: No matching key exchange found for host, their offer: diffie-hellman-group-exchange-sha1,diffie-hellman-group14-sha1

2021-05-31 23:25:35,779 -  nornir.core -     INFO -        run() - Running task 'send_command' with args {'command': 'show run'} on 3 hosts
2021-05-31 23:26:21,831 -  nornir.core -     INFO -        run() - Running task 'send_command' with args {'command': 'show run'} on 3 hosts
2021-05-31 23:28:25,682 -  nornir.core -     INFO -        run() - Running task 'send_command' with args {'command': 'show run'} on 3 hosts
2021-05-31 23:29:15,158 -  nornir.core -     INFO -        run() - Running task 'send_command' with args {'command': 'show run'} on 3 hosts
2021-05-31 23:30:18,144 -  nornir.core -     INFO -        run() - Running task 'send_command' with args {'command': 'show run'} on 3 hosts
2021-05-31 23:30:40,470 -  nornir.core -     INFO -        run() - Running task 'send_command' with args {'command': 'show run'} on 3 hosts
2021-05-31 23:31:12,301 -  nornir.core -     INFO -        run() - Running task 'send_command' with args {'command': 'show run'} on 3 hosts
2021-05-31 23:31:26,290 -  nornir.core -     INFO -        run() - Running task 'send_command' with args {'command': 'show run'} on 3 hosts
2021-05-31 23:31:51,798 -  nornir.core -     INFO -        run() - Running task 'send_command' with args {'command': 'show run'} on 3 hosts
2021-05-31 23:32:05,950 -  nornir.core -     INFO -        run() - Running task 'send_command' with args {'command': 'show run'} on 3 hosts
2021-05-31 23:32:17,835 -  nornir.core -     INFO -        run() - Running task 'send_command' with args {'command': 'show run'} on 3 hosts
2021-05-31 23:35:59,782 -  nornir.core -     INFO -        run() - Running task 'send_command' with args {'command': 'show version'} on 3 hosts
2021-05-31 23:37:39,551 -  nornir.core -     INFO -        run() - Running task 'send_command' with args {'command': 'show version'} on 3 hosts
2021-05-31 23:38:26,374 -  nornir.core -     INFO -        run() - Running task 'send_command' with args {'command': 'show version'} on 3 hosts
2021-05-31 23:39:17,986 -  nornir.core -     INFO -        run() - Running task 'send_command' with args {'command': 'show version'} on 3 hosts
2021-05-31 23:39:42,263 -  nornir.core -     INFO -        run() - Running task 'send_command' with args {'command': 'show version'} on 3 hosts
2021-05-31 23:40:32,545 -  nornir.core -     INFO -        run() - Running task 'send_command' with args {'command': 'show version'} on 3 hosts
2021-05-31 23:41:39,003 -  nornir.core -     INFO -        run() - Running task 'send_command' with args {'command': 'show version'} on 3 hosts
2021-05-31 23:42:37,305 -  nornir.core -     INFO -        run() - Running task 'send_command' with args {'command': 'show version'} on 3 hosts
2021-05-31 23:42:54,885 -  nornir.core -     INFO -        run() - Running task 'send_command' with args {'command': 'show version'} on 3 hosts
2021-05-31 23:44:16,950 -  nornir.core -     INFO -        run() - Running task 'send_command' with args {'command': 'show version'} on 3 hosts
2021-05-31 23:44:31,554 -  nornir.core -     INFO -        run() - Running task 'send_command' with args {'command': 'show version'} on 3 hosts
2021-05-31 23:45:09,337 -  nornir.core -     INFO -        run() - Running task 'send_command' with args {'command': 'show version'} on 3 hosts
2021-05-31 23:46:00,350 -  nornir.core -     INFO -        run() - Running task 'send_command' with args {'command': 'show version'} on 3 hosts
2021-05-31 23:46:26,918 -  nornir.core -     INFO -        run() - Running task 'send_command' with args {'command': 'show version'} on 3 hosts
2021-05-31 23:48:21,649 -  nornir.core -     INFO -        run() - Running task 'send_command' with args {'command': 'show version'} on 3 hosts
2021-05-31 23:49:26,932 -  nornir.core -     INFO -        run() - Running task 'send_command' with args {'command': 'show version'} on 3 hosts
2021-05-31 23:49:57,710 -  nornir.core -     INFO -        run() - Running task 'send_command' with args {'command': 'show version'} on 3 hosts
2021-05-31 23:52:38,971 -  nornir.core -  WARNING -        run() - Task 'send_command' has not been run – 0 hosts selected
2021-05-31 23:52:43,292 -  nornir.core -  WARNING -        run() - Task 'send_command' has not been run – 0 hosts selected
2021-05-31 23:53:17,663 -  nornir.core -  WARNING -        run() - Task 'send_command' has not been run – 0 hosts selected
2021-05-31 23:53:53,041 -  nornir.core -  WARNING -        run() - Task 'send_command' has not been run – 0 hosts selected
2021-05-31 23:54:24,556 -  nornir.core -     INFO -        run() - Running task 'send_command' with args {'command': 'show version'} on 1 hosts
2021-05-31 23:54:34,409 -  nornir.core -     INFO -        run() - Running task 'send_command' with args {'command': 'show version'} on 1 hosts
2021-05-31 23:54:41,245 -  nornir.core -     INFO -        run() - Running task 'send_command' with args {'command': 'show version'} on 1 hosts
2021-05-31 23:59:42,649 -  nornir.core -     INFO -        run() - Running task 'send_command' with args {'command': 'show version'} on 3 hosts
2021-06-01 00:00:02,328 -  nornir.core -     INFO -        run() - Running task 'send_command' with args {'command': 'show version'} on 1 hosts
